Workbook

Sheet サマリ
A1: SWEBOK Guide v4.0a（固定参照版）・クラウドWell-Architected Framework参照・整合 開発レビューチェックリスト
A2: 更新: 2026-07-18 / SWEBOK参照版: v4.0a / .workspace/swebok-v4a.pdf (SHA-256: b3cb8028fecb9607f757504c861947fa3bf423087ea8bf08c58020f0ba3596dc)。全18KAとの関係と適用・除外理由は「KA対応表」を参照。WAFは規範的な一律要件ではなく、案件条件に基づき適用判定する。各レビューシートに適用／N/A、Pass／Fail、証跡、指摘、例外承認、再確認の実施記録列を追加。出典は「出典マスター」、運用は「利用ガイド」、追加承認65件は「追加項目管理」を参照。
A4: 領域 | B4: シート | C4: 対象ドキュメント | D4: 項目数（数式） | E4: Critical | F4: High | G4: Medium | H4: Low | I4: カバレッジ総評
A5: ソフトウェア要件定義 | B5: 01_要件定義 | C5: swebok-v4a.pdf ch01 Software Requirements | D5: =COUNTA('01_要件定義'!$A$2:$A$89) | E5: =COUNTIF('01_要件定義'!$D$2:$D$89,"Critical") | F5: =COUNTIF('01_要件定義'!$D$2:$D$89,"High") | G5: =COUNTIF('01_要件定義'!$D$2:$D$89,"Medium") | H5: =COUNTIF('01_要件定義'!$D$2:$D$89,"Low") | I5: チェックリストはSWEBOK v4 第1章の主要トピック(要求の分類、獲得、分析、仕様化、妥当性確認、管理、優先順位付け・トレーサビリティ・計測、ツール)をほぼ網羅しており、ISO 29148/25010による実務補完も適切。特に3.1の望ましい性質(曖昧性・テスト可能性・原子性等)と6章の管理活動(スクラビング・変更管理・スコープマッチング)のカバーが厚い。一方、3.4「要求間対立への対処」の解決プロセス記録、QoS制約間の相互関係・トレードオフ(1.5/3.2)、7.6「要求プロセスの品質と改善」が手薄であり、gap として補完を提案する。
A6: ソフトウェアアーキテクチャ設計 | B6: 02_アーキテクチャ | C6: swebok-v4a.pdf ch02 Software Architecture | D6: =COUNTA('02_アーキテクチャ'!$A$2:$A$83) | E6: =COUNTIF('02_アーキテクチャ'!$D$2:$D$83,"Critical") | F6: =COUNTIF('02_アーキテクチャ'!$D$2:$D$83,"High") | G6: =COUNTIF('02_アーキテクチャ'!$D$2:$D$83,"Medium") | H6: =COUNTIF('02_アーキテクチャ'!$D$2:$D$83,"Low") | I6: SWEBOK v4 第2章(Software Architecture)の4トピック(基礎/記述/プロセス/評価)を、10カテゴリ76項目でほぼ網羅的にカバーしている。特に2.4(重要決定・根拠・技術的負債)、2.1(ビュー/ビューポイント)、4章(評価・レビュー・メトリクス)への対応が厚く、実務補完(観測可能性、ライセンス、Docs as Code等)も適切に織り込まれている。一方、1.3の再利用・プロダクトライン、3.4のアーキテクチャ知識管理、3.1のライフサイクルコンテキスト(アジャイル等での創発的アーキテクチャのリスク)への対応がやや手薄である。
A7: ソフトウェア詳細設計 | B7: 03_詳細設計 | C7: swebok-v4a.pdf ch03 Software Design | D7: =COUNTA('03_詳細設計'!$A$2:$A$98) | E7: =COUNTIF('03_詳細設計'!$D$2:$D$98,"Critical") | F7: =COUNTIF('03_詳細設計'!$D$2:$D$98,"High") | G7: =COUNTIF('03_詳細設計'!$D$2:$D$98,"Medium") | H7: =COUNTIF('03_詳細設計'!$D$2:$D$98,"Low") | I7: SWEBOK v4 CHAPTER 03(Software Design)の主要トピックはおおむねカバーされている。特に設計原則(1.4)、詳細設計の対象(2.2)、設計品質特性(3.1〜3.8)、記録・根拠(4章)、レビューと評価(6章)に対応する項目が体系的に配置されている。一方、既製コンポーネント/フレームワーク再利用の検討(2.2/5.6)、セーフティ(3.7)、外部システムとの統合・相互運用性(3.6)、採用設計手法の明示(5章)がやや手薄である。API仕様・DB実務・Web UI 実務の項目は SWEBOK を実務標準で補完したものとして妥当である。
A8: ソフトウェア実装 | B8: 04_実装 | C8: swebok-v4a.pdf ch04 Software Construction | D8: =COUNTA('04_実装'!$A$2:$A$86) | E8: =COUNTIF('04_実装'!$D$2:$D$86,"Critical") | F8: =COUNTIF('04_実装'!$D$2:$D$86,"High") | G8: =COUNTIF('04_実装'!$D$2:$D$86,"Medium") | H8: =COUNTIF('04_実装'!$D$2:$D$86,"Low") | I8: SWEBOK v4 第4章の中核である構築の基礎(複雑性最小化・検証可能性・標準適用)、構築技術(エラー処理・防御的プログラミング・並行処理・API設計・性能)、管理(依存関係・統合・CI)、構築テストをコードレビュー実務の観点で幅広くカバーしており、実務補完(セキュアコーディング詳細、レビュー記録)も適切に組み込まれている。一方、2.3 構築の計測、3.5 再利用のための構築(可変性の実装・資産の文書化)、4.8 実行時コンフィギュレーションと国際化はチェック項目が手薄である。4.6〜4.7(実行可能モデル、状態ベース/テーブル駆動)や4.13(ヘテロジニアスシステム)は適用場面が限定的であり、汎用チェックリストからの除外は妥当と判断する。
A9: ソフトウェアテスト | B9: 05_テスト | C9: swebok-v4a.pdf ch05 Software Testing | D9: =COUNTA('05_テスト'!$A$2:$A$91) | E9: =COUNTIF('05_テスト'!$D$2:$D$91,"Critical") | F9: =COUNTIF('05_テスト'!$D$2:$D$91,"High") | G9: =COUNTIF('05_テスト'!$D$2:$D$91,"Medium") | H9: =COUNTIF('05_テスト'!$D$2:$D$91,"Low") | I9: チェックリストはSWEBOK v4 第5章の主要トピック(テストレベル、仕様/構造/経験ベース技法、テストプロセス、測定、完了判定)を計画〜報告のライフサイクル全体にわたり高い密度でカバーしており、フォールト/フェイラの区別やオラクル問題、テスト理論の限界といった基礎概念も項目に反映されている。一方、SWEBOKが独立トピックとして扱う利用ベース技法(運用プロファイルによる信頼性評価)、テスト容易性、適合・コンプライアンステスト、アルファ/ベータテスト、テストツール選定は既存項目で明示的にカバーされていない。自動テストコードのカテゴリはSWEBOK記述を超える実務補完だが、シフトレフト開発(6.1.2)の趣旨と整合している。
A10: ソフトウェア運用 | B10: 06_運用 | C10: swebok-v4a.pdf ch06 SE Operations | D10: =COUNTA('06_運用'!$A$2:$A$106) | E10: =COUNTIF('06_運用'!$D$2:$D$106,"Critical") | F10: =COUNTIF('06_運用'!$D$2:$D$106,"High") | G10: =COUNTIF('06_運用'!$D$2:$D$106,"Medium") | H10: =COUNTIF('06_運用'!$D$2:$D$106,"Low") | I10: SWEBOK v4 第6章(Software Engineering Operations)の3大プロセス(計画・デリバリー・統制)と実践的考慮事項・ツールをほぼ全域にわたりカバーしており、SLO/エラーバジェットや Runbook 具体性などSRE実務の補完も適切である。一方、運用計画の柱である財務管理・予算(2.1.1)、情報セキュリティリスクアセスメントとポリシー/教育(2.6)、承認外構成変更の検知(4.3)、継続的な運用リスク管理とリスク許容度の合意(5.2)が手薄であり、これらを補うことで章構成との対応が完全に近くなる。
A11: ソフトウェア保守 | B11: 07_保守 | C11: swebok-v4a.pdf ch07 Software Maintenance | D11: =COUNTA('07_保守'!$A$2:$A$87) | E11: =COUNTIF('07_保守'!$D$2:$D$87,"Critical") | F11: =COUNTIF('07_保守'!$D$2:$D$87,"High") | G11: =COUNTIF('07_保守'!$D$2:$D$87,"Medium") | H11: =COUNTIF('07_保守'!$D$2:$D$87,"Low") | I11: チェックリストは SWEBOK v4 第7章の主要トピック(保守区分、影響分析、保守性・技術的負債、リファクタリング/リエンジニアリング、テスト、SCM、供給者管理・SLA、測定、プロセス、プログラム理解)をほぼ網羅しており、EOL・移行・廃棄など ISO/IEC/IEEE 14764 の Disposal 側も実務的に補完している。一方、章が明示する「保守区分別のコスト/工数傾向分析」「リリース/バージョン計画の利用者合意・競合調整」「継続的デリバリー/デプロイの自動化」「稼働ソフトウェアのサーベイランス(容量・継続性・可用性)」はやや手薄である。全体として SWEBOK 準拠度は高く、追加提案は4件にとどまる。
A12: ソフトウェア構成管理 | B12: 08_構成管理 | C12: swebok-v4a.pdf ch08 Software Configuration Management | D12: =COUNTA('08_構成管理'!$A$2:$A$97) | E12: =COUNTIF('08_構成管理'!$D$2:$D$97,"Critical") | F12: =COUNTIF('08_構成管理'!$D$2:$D$97,"High") | G12: =COUNTIF('08_構成管理'!$D$2:$D$97,"Medium") | H12: =COUNTIF('08_構成管理'!$D$2:$D$97,"Low") | I12: SWEBOK v4 第8章の6大トピック(SCMプロセス管理、構成識別、変更管理、状況記録、構成監査、リリース管理・配布)とツール(7節)をすべてカバーし、ブランチ戦略・バージョニング・CI/CDといった実務領域も8-1.3/8-2.3/8-6.1由来として体系的に展開している。デビエーション/ウェーバー、FCA/PCA、SBOMなど形式的な要素も漏れなく項目化されており、章構成に対するカバレッジは高い。一方、ソフトウェアライブラリのバックアップ・復旧(2.6節)、リリース配布先の追跡(6.2節)、ツール移行性(1.3.3節)の3点が手薄であり、gapsとして補完を提案する。
A13: SEマネジメント | B13: 09_マネジメント | C13: swebok-v4a.pdf ch09 SE Management | D13: =COUNTA('09_マネジメント'!$A$2:$A$94) | E13: =COUNTIF('09_マネジメント'!$D$2:$D$94,"Critical") | F13: =COUNTIF('09_マネジメント'!$D$2:$D$94,"High") | G13: =COUNTIF('09_マネジメント'!$D$2:$D$94,"Medium") | H13: =COUNTIF('09_マネジメント'!$D$2:$D$94,"Low") | I13: SWEBOK v4 第9章(Software Engineering Management)の7トピック(開始と適用範囲の定義、計画、実行、レビューと評価、終結、測定、ツール)を、チェックリストの14カテゴリでほぼ網羅している。特に計画(SDLC選定・見積り・リスク・品質)と監視統制・測定(15939準拠)の対応が厚い。一方、1.1「要求の決定と交渉」の実施確認、リスクの機会(ポジティブリスク)側面、4.2の要員パフォーマンスレビュー、6.1の測定コミットメント(資源・責任)、3.2の契約形態・知財条項が手薄であり、gapsとして補完を提案する。
A14: SEプロセス | B14: 10_プロセス | C14: swebok-v4a.pdf ch10 SE Process | D14: =COUNTA('10_プロセス'!$A$2:$A$96) | E14: =COUNTIF('10_プロセス'!$D$2:$D$96,"Critical") | F14: =COUNTIF('10_プロセス'!$D$2:$D$96,"High") | G14: =COUNTIF('10_プロセス'!$D$2:$D$96,"Medium") | H14: =COUNTIF('10_プロセス'!$D$2:$D$96,"Low") | I14: チェックリストはSWEBOK v4 第10章の主要トピック(プロセス定義の3要素と統制・実現メカニズム、ライフサイクルモデルの類型と選定根拠、12207の4プロセスカテゴリ、テーラリング、GQMベースの計測、モニタリング、PDCA/フレームワークベースのアセスメントと改善、レトロスペクティブ、プロセスインフラ・ツール統合)をほぼ網羅している。特に2.4〜2.5のライフサイクルパラダイムとアジャイルの誤解、2.8のテーラリング、3章のアセスメント・改善は手厚い。一方、2.9が明言する「測定・見積もりの精度と不確実性レベルの定義」、2.5の大規模アジャイル適用の難しさ、2.6の段階間遷移の仕様化はやや手薄であり、gapとして補完を提案する。
A15: ソフトウェア品質保証 | B15: 12_品質保証 | C15: swebok-v4a.pdf ch12 Software Quality | D15: =COUNTA('12_品質保証'!$A$2:$A$92) | E15: =COUNTIF('12_品質保証'!$D$2:$D$92,"Critical") | F15: =COUNTIF('12_品質保証'!$D$2:$D$92,"High") | G15: =COUNTIF('12_品質保証'!$D$2:$D$92,"Medium") | H15: =COUNTIF('12_品質保証'!$D$2:$D$92,"Low") | I15: チェックリストはSWEBOK v4 第12章の主要構成(品質基礎、品質コスト、標準・インテグリティレベル、SQM計画/SQAP、品質測定、プロセス保証・プロダクト保証、V&V、レビュー/監査、欠陥分析・CAPA、ツール)をほぼ網羅しており、品質ゲート(第7カテゴリ)はSWEBOKのマイルストーン評価・技術レビュー群を実務向けに具体化した妥当な補完である。一方、SQAPが明示的に扱うべきとされる供給者/COTS調達ソフトへの品質保証、QMS運営の前提となる経営層のコミットメント、安全ハザード分析(FMEA/FTA)、V&Vを支える成果物間トレーサビリティの4点が手薄であり、gapとして追加を提案する。全体としてカバレッジは高く、既存項目の粒度・判定基準も客観的で実用に耐える。
A16: ソフトウェアセキュリティ | B16: 13_セキュリティ | C16: swebok-v4a.pdf ch13 Software Security | D16: =COUNTA('13_セキュリティ'!$A$2:$A$105) | E16: =COUNTIF('13_セキュリティ'!$D$2:$D$105,"Critical") | F16: =COUNTIF('13_セキュリティ'!$D$2:$D$105,"High") | G16: =COUNTIF('13_セキュリティ'!$D$2:$D$105,"Medium") | H16: =COUNTIF('13_セキュリティ'!$D$2:$D$105,"Low") | I16: チェックリストはSWEBOK v4 第13章の主要トピック(セキュリティ要件・設計・構築・テスト・脆弱性管理・ツール・ドメイン固有・マネジメント)をほぼ網羅し、特に4章(Security Engineering for Software Systems)と6章(Domain-Specific)は密度高くカバーしている。CERT Top 10やCVE/CWE/CVSS、ISMS、SSE-CMM、アジャイルプラクティスなど章内の具体的言及にも対応項目がある。一方、3.2 Common Criteria(ISO/IEC 15408)によるセキュリティ評価、1.3 サイバーセキュリティのソーシャルエンジニアリング系脅威、4.2 の攻撃許容(被害限定・安全な復旧)の観点は手薄である。全体としてSWEBOK準拠度は高く、OWASP ASVS/Top 10等の実務標準による補完も適切である。
A17: クラウド共通 | B17: 14_クラウド | C17: 各社Well-Architected系フレームワーク共通 | D17: =COUNTA('14_クラウド'!$A$2:$A$67) | E17: =COUNTIF('14_クラウド'!$D$2:$D$67,"Critical") | F17: =COUNTIF('14_クラウド'!$D$2:$D$67,"High") | G17: =COUNTIF('14_クラウド'!$D$2:$D$67,"Medium") | H17: =COUNTIF('14_クラウド'!$D$2:$D$67,"Low") | I17: 4フレームワークのcommonThemes計131件を意味的に統合し、信頼性・セキュリティ・コスト最適化・運用・パフォーマンス・持続可能性/ガバナンスの6カテゴリ64項目に集約した。IAM最小権限・マルチゾーン冗長・IaC・暗号化・タグ付けなど4FW共通の中核概念は1項目に統合し出典を併記、FMA・SLO/エラーバジェット・責任共有モデル等の特定FW固有の優良観点も漏れなく採録した。重要度は統合元の最高値を採用しており、131件すべてがいずれかの項目に対応付いている。
A18: AWS | B18: 15_AWS | C18: AWS Well-Architected Framework(+ Generative AI Lens) | D18: =COUNTA('15_AWS'!$A$2:$A$130) | E18: =COUNTIF('15_AWS'!$D$2:$D$130,"Critical") | F18: =COUNTIF('15_AWS'!$D$2:$D$130,"High") | G18: =COUNTIF('15_AWS'!$D$2:$D$130,"Medium") | H18: =COUNTIF('15_AWS'!$D$2:$D$130,"Low")
A19: Google Cloud | B19: 16_GoogleCloud | C19: Google Cloud Well-Architected Framework(+ Architecture Center AI & ML) | D19: =COUNTA('16_GoogleCloud'!$A$2:$A$123) | E19: =COUNTIF('16_GoogleCloud'!$D$2:$D$123,"Critical") | F19: =COUNTIF('16_GoogleCloud'!$D$2:$D$123,"High") | G19: =COUNTIF('16_GoogleCloud'!$D$2:$D$123,"Medium") | H19: =COUNTIF('16_GoogleCloud'!$D$2:$D$123,"Low")
A20: Azure | B20: 17_Azure | C20: Azure Well-Architected Framework(+ AI workloads) | D20: =COUNTA('17_Azure'!$A$2:$A$152) | E20: =COUNTIF('17_Azure'!$D$2:$D$152,"Critical") | F20: =COUNTIF('17_Azure'!$D$2:$D$152,"High") | G20: =COUNTIF('17_Azure'!$D$2:$D$152,"Medium") | H20: =COUNTIF('17_Azure'!$D$2:$D$152,"Low")
A21: OCI | B21: 18_OCI | C21: OCI Well-Architected Framework | D21: =COUNTA('18_OCI'!$A$2:$A$81) | E21: =COUNTIF('18_OCI'!$D$2:$D$81,"Critical") | F21: =COUNTIF('18_OCI'!$D$2:$D$81,"High") | G21: =COUNTIF('18_OCI'!$D$2:$D$81,"Medium") | H21: =COUNTIF('18_OCI'!$D$2:$D$81,"Low")
A22: AI(共通) | B22: 19_AI | C22: AWS GenAI Lens / Azure WAF AI workloads / Google Cloud AI&ML 横断 | D22: =COUNTA('19_AI'!$A$2:$A$81) | E22: =COUNTIF('19_AI'!$D$2:$D$81,"Critical") | F22: =COUNTIF('19_AI'!$D$2:$D$81,"High") | G22: =COUNTIF('19_AI'!$D$2:$D$81,"Medium") | H22: =COUNTIF('19_AI'!$D$2:$D$81,"Low") | I22: 3フレームワークの commonThemes 81件を意味的に統合し、AIライフサイクル(企画→データ→モデル→評価→デプロイ→運用→改善)と横断関心(セキュリティ、責任あるAI、信頼性、コスト)を10カテゴリ51項目に再構成した。プロンプトインジェクション・ガードレール・モデル評価基準・ドリフト監視・推論コスト管理など3社共通の中核テーマは1項目に統合し全出典を併記、単一フレームワーク由来の固有観点(セキュリティトリミング、チェックポイント戦略、サステナビリティ等)も漏れなく採録した。重要度は統合元の最高値を採用しており、生成AI・従来型MLの双方に適用可能なベンダー中立チェックリストとして網羅性は高い。
A23: 合計 | D23: =SUM(D5:D22) | E23: =SUM(E5:E22) | F23: =SUM(F5:F22) | G23: =SUM(G5:G22) | H23: =SUM(H5:H22) | I23: 件数は基準重要度の集計。案件重要度・判定結果は各レビュー実施時に記録する。

Sheet 利用ガイド
A1: 利用ガイド — 適用、判定、重複統制、リリースゲート
A3: 位置づけ | B3: SWEBOK Guide v4.0aと各社Well-Architected Frameworkを参照・整合させたレビュー観点マスター兼実施記録。規格認証や全SWEBOK KAへの完全準拠を表明するものではない。
A4: SWEBOK参照版 | B4: ローカルの .workspace/swebok-v4a.pdf を固定参照版とする（SHA-256: b3cb8028fecb9607f757504c861947fa3bf423087ea8bf08c58020f0ba3596dc）。PDF本体は再配布しない。
A5: SWEBOK対象範囲 | B5: 全18 KAを対応付ける。KA 1〜10・12・13は直接参照、KA 11・14・15は部分整合、KA 16〜18は前提知識として理由付き対象外。詳細は「KA対応表」を参照。
A6: WAFの扱い | B6: WAFは設計判断・リスク・トレードオフを評価する助言資料。各項目は案件のSLO、RTO/RPO、規制、データ分類、費用制約を入力に適用判定する。
A8: 適用プロファイル
A9: プロファイル | B9: 適用順 | C9: 対象 | D9: 利用シート | E9: 重複時の扱い
A10: CORE | B10: 1 | C10: 原則全案件 | D10: 01〜10、12、13 | E10: まず評価する
A11: CLOUD-COMMON | B11: 2 | C11: クラウド利用案件 | D11: 14_クラウド | E11: Coreの証跡を再利用可
A12: AWS/GCP/AZURE/OCI-DELTA | B12: 3 | C12: 採用ベンダーのみ | D12: 15〜18の該当1シート | E12: 共通で未評価の固有差分を追加
A13: AI-CONDITIONAL | B13: 4 | C13: AI/ML利用案件 | D13: 19_AI | E13: 従来ML・生成AI・Agenticの種別でN/A判断
A15: レビュー実施手順
A16: 1. 適用プロファイルを選び、各行の「適用判定」を適用／N/Aで記録する。N/Aは「証跡・参照箇所」に根拠を残す。
A17: 2. 基準重要度を助言値として、案件の重要度・データ分類・規制・SLOを反映した「案件重要度」と判断根拠を設定する。
A18: 3. Pass／Fail／未確認を記録し、Passは証跡、Failは指摘・Issue ID、対応方針、是正期限、担当情報を残す。
A19: 4. N/Aにもレビュアーと日付を残す。Fail是正後は明示的な再確認記録によりPassを確認し、変更履歴を保持する。
A21: 重要度とゲート
A22: 区分 | B22: 定義 | C22: 運用
A23: 基準重要度 | B23: 観点が一般に持つ潜在影響。マスター側の初期値。 | C23: 案件固有のリリース判定を単独では決めない。
A24: 案件重要度 | B24: 対象システムの重要度、規制、データ、SLO、露出度を反映した実行時評価。 | C24: レビュー責任者が根拠とともに設定する。
A25: 案件Critical | B25: 適用かつ未解決のFailが重大事故・法令違反・受入不能へ直結する。 | C25: 原則リリース停止。例外は記名承認と期限付きリスク受容が必要。
A27: 重複統制ルール
A28: • 同じリスクがCore、Cloud Common、ベンダー、AIに現れる場合、先に実施した証跡を再利用してよい。
A29: • 共通統制で十分に評価済みのベンダー行はN/Aとし、「証跡・参照箇所」に評価済みIDを記載する。ベンダー固有差分がある場合だけ別判定する。
A30: • 同じ根本リスクは同一のIssue IDを使用し、件数・リスク集計ではIssue IDを一意に数える。行数の合算をリスク件数にしない。
A31: • 「重複統制グループ」は候補を機械付与した補助情報。最終的な同一統制判断は証跡・対象資産・要求を確認して行う。
A33: 追加承認の移行注意
A34: 旧ブックで「追加承認」とされた65件は「追加項目管理」へ全件接続した。ただし旧ブックには承認者・承認日の原記録がないため、状態を「要原記録確認」としている。利用開始前に実在する承認記録で補完し、未確認のまま承認済みと扱わない。

Sheet 出典マスター
A1: 出典マスター
A3: Source ID | B3: 正式名称 | C3: 版・公開日 | D3: URL | E3: 参照日 | F3: 適用範囲 | G3: 変更確認日 | H3: 前版との差分 | I3: 固定参照物 | J3: 注記
A4: SRC-SWEBOK-V4A | B4: Guide to the Software Engineering Body of Knowledge (SWEBOK Guide) v4.0a | C4: v4.0a / 2025-09（ローカル固定参照版） | D4: https://www.computer.org/education/bodies-of-knowledge/software-engineering | E4: 46221 | F4: 全18KAを対応付け、KA 1〜10・12・13を直接参照、KA 11・14・15を部分整合、KA 16〜18を理由付き対象外とする。 | G4: 46221 | H4: v4.0から2025年9月の軽微改訂版v4.0aへ更新。完全準拠ではなく対象範囲を明示した参照・整合へ位置付けを修正。 | I4: .workspace/swebok-v4a.pdf / SHA-256 b3cb8028fecb9607f757504c861947fa3bf423087ea8bf08c58020f0ba3596dc | J4: 添付物の同一性だけを固定し、PDF本体は再配布しない。
A5: SRC-AWS-WAF | B5: AWS Well-Architected Framework | C5: 継続更新 | D5: https://docs.aws.amazon.com/wellarchitected/latest/framework/welcome.html | E5: 46221 | F5: AWSおよびクラウド共通 | G5: 46221 | H5: 前回登録内容から適用範囲・版の変更なし。 | J5: 継続更新型資料は変更確認日に再確認する。
A6: SRC-AWS-GENAI | B6: AWS Well-Architected Generative AI Lens | C6: 継続更新 | D6: https://docs.aws.amazon.com/wellarchitected/latest/generative-ai-lens/generative-ai-lens.html | E6: 46221 | F6: 生成AI | G6: 46221 | H6: 2025年11月19日公開の現行Generative AI Lensを生成AI用途へ対応付け。 | J6: 継続更新型資料は変更確認日に再確認する。
A7: SRC-AWS-RAI | B7: AWS Well-Architected Responsible AI Lens | C7: 2025-11-19 | D7: https://docs.aws.amazon.com/wellarchitected/latest/responsible-ai-lens/responsible-ai-lens.html | E7: 46221 | F7: 責任あるAI | G7: 46221 | H7: 2025年11月19日公開のResponsible AI Lensを追加し、案件固有の考慮事項として扱う。 | J7: 継続更新型資料は変更確認日に再確認する。
A8: SRC-AWS-ML | B8: AWS Well-Architected Machine Learning Lens | C8: 2025-11-19 | D8: https://docs.aws.amazon.com/wellarchitected/latest/machine-learning-lens/machine-learning-lens.html | E8: 46221 | F8: 従来型MLを含むML全般 | G8: 46221 | H8: 2025年11月19日公開のMachine Learning Lensを従来型ML用途へ追加。 | J8: 継続更新型資料は変更確認日に再確認する。
A9: SRC-AWS-AGENTIC | B9: AWS Well-Architected Agentic AI Lens | C9: 2026-06-10 | D9: https://docs.aws.amazon.com/wellarchitected/latest/agentic-ai-lens/agentic-ai-lens.html | E9: 46221 | F9: エージェントAI | G9: 46221 | H9: 2026年6月10日公開のAgentic AI Lensを追加し、自律性・追跡・監督の統制へ対応付け。 | J9: 継続更新型資料は変更確認日に再確認する。
A10: SRC-GCP-WAF | B10: Google Cloud Well-Architected Framework | C10: 継続更新 | D10: https://cloud.google.com/architecture/framework | E10: 46221 | F10: Google Cloudおよびクラウド共通 | G10: 46221 | H10: 前回登録内容から適用範囲・版の変更なし。 | J10: 継続更新型資料は変更確認日に再確認する。
A11: SRC-GCP-AIML | B11: Google Cloud Well-Architected Framework: AI and ML perspective | C11: 2024-10-11 review | D11: https://cloud.google.com/architecture/framework/perspectives/ai-ml | E11: 46221 | F11: AI/ML | G11: 46221 | H11: AI/ML perspectiveを一般WAFから分離してAI条件付きプロファイルへ対応付け。 | J11: 継続更新型資料は変更確認日に再確認する。
A12: SRC-AZR-WAF | B12: Microsoft Azure Well-Architected Framework | C12: 継続更新 | D12: https://learn.microsoft.com/en-us/azure/well-architected/ | E12: 46221 | F12: Azureおよびクラウド共通 | G12: 46221 | H12: 前回登録内容から適用範囲・版の変更なし。 | J12: 継続更新型資料は変更確認日に再確認する。
A13: SRC-AZR-AI | B13: AI Workload Documentation - Azure Well-Architected Framework | C13: 継続更新 | D13: https://learn.microsoft.com/en-us/azure/well-architected/ai/ | E13: 46221 | F13: Azure AI/ML | G13: 46221 | H13: Azure AI Workload資料を一般WAFから分離してAI条件付きプロファイルへ対応付け。 | J13: 継続更新型資料は変更確認日に再確認する。
A14: SRC-OCI-WAF | B14: Well-architected framework for Oracle Cloud Infrastructure | C14: F29550-09 / 2025-05 | D14: https://docs.oracle.com/en/solutions/oci-best-practices/toc.htm | E14: 46221 | F14: OCIおよびクラウド共通 | G14: 46221 | H14: 前回登録内容から適用範囲・版の変更なし。 | J14: 継続更新型資料は変更確認日に再確認する。
A15: SRC-ISO-29148 | B15: ISO/IEC/IEEE 29148 Systems and software engineering — Life cycle processes — Requirements engineering | C15: 参照記載版 | D15: https://www.iso.org/standard/72089.html | E15: 46221 | F15: 要求工学の実務補完 | G15: 46221 | H15: 前回登録内容から適用範囲・版の変更なし。 | J15: 継続更新型資料は変更確認日に再確認する。
A16: SRC-ISO-25010 | B16: ISO/IEC 25010 Systems and software Quality Requirements and Evaluation | C16: 参照記載版 | D16: https://www.iso.org/standard/78176.html | E16: 46221 | F16: 品質モデルの実務補完 | G16: 46221 | H16: 前回登録内容から適用範囲・版の変更なし。 | J16: 継続更新型資料は変更確認日に再確認する。
... A25: SRC-IEEE-GENERAL | B25: IEEE standards and guidance（項目の参照箇所に規格番号を記載） | C25: 各参照記載版 | D25: https://standards.ieee.org/ | E25: 46221 | F25: その他IEEE参照 | G25: 46221 | H25: 前回登録内容から適用範囲・版の変更なし。 | J25: 継続更新型資料は変更確認日に再確認する。
A26: SRC-PRACTICE | B26: 組織・案件固有の実務補完 | C26: 案件ごとに根拠を登録 | E26: 46221 | F26: 外部規範ではない。証跡欄に組織標準・意思決定記録を添付する。 | G26: 46221 | H26: 前回登録内容から適用範囲・版の変更なし。 | J26: 継続更新型資料は変更確認日に再確認する。

Sheet KA対応表
A1: SWEBOK v4.0a Knowledge Area 対応表
A3: KA | B3: Knowledge Area | C3: 扱い | D3: 対応シート | E3: 適用範囲・除外根拠 | F3: 主な証跡 | G3: 備考
A4: 1 | B4: Software Requirements | C4: 直接参照 | D4: 01_要件定義 | E4: レビュー対象 | F4: 要求仕様・トレーサビリティ
A5: 2 | B5: Software Architecture | C5: 直接参照 | D5: 02_アーキテクチャ | E5: レビュー対象 | F5: アーキテクチャ記述・意思決定
A6: 3 | B6: Software Design | C6: 直接参照 | D6: 03_詳細設計 | E6: レビュー対象 | F6: 詳細設計・API/DB/UI設計
A7: 4 | B7: Software Construction | C7: 直接参照 | D7: 04_実装 | E7: レビュー対象 | F7: コード・実装規約・ビルド
A8: 5 | B8: Software Testing | C8: 直接参照 | D8: 05_テスト | E8: レビュー対象 | F8: テスト計画・設計・結果
A9: 6 | B9: Software Engineering Operations | C9: 直接参照 | D9: 06_運用 | E9: レビュー対象 | F9: 運用設計・Runbook・SLO
A10: 7 | B10: Software Maintenance | C10: 直接参照 | D10: 07_保守 | E10: レビュー対象 | F10: 保守計画・変更・廃止
A11: 8 | B11: Software Configuration Management | C11: 直接参照 | D11: 08_構成管理 | E11: レビュー対象 | F11: 構成識別・変更・リリース
A12: 9 | B12: Software Engineering Management | C12: 直接参照 | D12: 09_マネジメント | E12: レビュー対象 | F12: 計画・見積・リスク・測定
A13: 10 | B13: Software Engineering Process | C13: 直接参照 | D13: 10_プロセス | E13: レビュー対象 | F13: プロセス定義・評価・改善
A14: 11 | B14: Software Engineering Models and Methods | C14: 部分整合（独立シートなし） | D14: 02/03/05/10/12 | E14: モデル・形式手法・レビュー方法を各工程で条件付き評価。方法論全体の網羅は対象外。 | F14: モデル、分析・レビュー記録 | G14: 独立KA準拠は表明しない
A15: 12 | B15: Software Quality | C15: 直接参照 | D15: 12_品質保証 | E15: レビュー対象 | F15: 品質計画・保証・測定
A16: 13 | B16: Software Security | C16: 直接参照 | D16: 13_セキュリティ | E16: レビュー対象 | F16: 脅威モデル・セキュリティ設計/試験
A17: 14 | B17: Software Engineering Professional Practice | C17: 部分整合（独立シートなし） | D17: 01/09/10/12/19 | E17: コミュニケーション、倫理、責任あるAIの成果物化された部分のみ。専門職実践全体は対象外。 | F17: 合意記録・役割・倫理審査 | G17: 独立KA準拠は表明しない
A18: 15 | B18: Software Engineering Economics | C18: 部分整合（独立シートなし） | D18: 09/14〜19 | E18: 見積、投資、クラウド/AIコスト、トレードオフのみ。経済学体系全体は対象外。 | F18: Business case・TCO・予算 | G18: 独立KA準拠は表明しない
A19: 16 | B19: Computing Foundations | C19: 対象外（前提知識） | D19: — | E19: 個別成果物レビューではなく実務者の基礎知識。必要な技術事項は各工程で評価。 | F19: — | G19: 適用除外
A20: 17 | B20: Mathematical Foundations | C20: 対象外（前提知識） | D20: — | E20: 個別成果物レビューではなく基礎知識。安全・形式検証案件では条件付きで方法を評価。 | F20: — | G20: 適用除外
A21: 18 | B21: Engineering Foundations | C21: 対象外（前提知識） | D21: — | E21: 個別成果物レビューではなく工学基礎。安全・規制領域は案件プロファイルで補完。 | F21: — | G21: 適用除外

Sheet 追加項目管理
A1: 追加承認項目の由来・承認記録
A3: 追加ID | B3: シート | C3: 追加理由／不足トピック | D3: 追加チェック項目 | E3: 根拠資料 | F3: 出典ID | G3: 承認状態 | H3: 承認者 | I3: 承認日 | J3: 変更理由 | K3: 注記
A4: REQ-901 | B4: 01_要件定義 | C4: 旧ブックで追加承認として登録（カテゴリ: 10. 妥当性確認(SWEBOK 5.1〜5.3)） | D4: 要求レビューが実施され記録がある | E4: swebok-v4a.pdf ch01 Software Requirements > 5.1 Requirements Reviews | F4: SRC-SWEBOK-V4A | G4: 要原記録確認 | H4: 未記録 | I4: 未記録 | J4: 旧ブックに追加理由・原承認記録なし。原記録の確認が必要。 | K4: 旧ブックの「追加承認」表記を移行。承認者・日付を推測で補完しない。
A5: REQ-902 | B5: 01_要件定義 | C5: 旧ブックで追加承認として登録（カテゴリ: 10. 妥当性確認(SWEBOK 5.1〜5.3)） | D5: レビューが複数視点で行われている | E5: swebok-v4a.pdf ch01 Software Requirements > 5.1 Requirements Reviews(review from multiple perspectives) | F5: SRC-SWEBOK-V4A | G5: 要原記録確認 | H5: 未記録 | I5: 未記録 | J5: 旧ブックに追加理由・原承認記録なし。原記録の確認が必要。 | K5: 旧ブックの「追加承認」表記を移行。承認者・日付を推測で補完しない。
A6: REQ-903 | B6: 01_要件定義 | C6: 旧ブックで追加承認として登録（カテゴリ: 10. 妥当性確認(SWEBOK 5.1〜5.3)） | D6: Critical/High 指摘がクローズされている | E6: swebok-v4a.pdf ch01 Software Requirements > 5.1 Requirements Reviews / 実務補完(レビュープロセス実務) | F6: SRC-SWEBOK-V4A;SRC-PRACTICE | G6: 要原記録確認 | H6: 未記録 | I6: 未記録 | J6: 旧ブックに追加理由・原承認記録なし。原記録の確認が必要。 | K6: 旧ブックの「追加承認」表記を移行。承認者・日付を推測で補完しない。
A7: REQ-904 | B7: 01_要件定義 | C7: 旧ブックで追加承認として登録（カテゴリ: 10. 妥当性確認(SWEBOK 5.1〜5.3)） | D7: 主要ステークホルダーの承認記録がある | E7: swebok-v4a.pdf ch01 Software Requirements > 1.11 Software Requirements Activities(reaching an agreement)/ 5. Requirements Validation | F7: SRC-SWEBOK-V4A | G7: 要原記録確認 | H7: 未記録 | I7: 未記録 | J7: 旧ブックに追加理由・原承認記録なし。原記録の確認が必要。 | K7: 旧ブックの「追加承認」表記を移行。承認者・日付を推測で補完しない。
A8: REQ-905 | B8: 01_要件定義 | C8: 旧ブックで追加承認として登録（カテゴリ: 10. 妥当性確認(SWEBOK 5.1〜5.3)） | D8: 誤解リスクの高い箇所にプロトタイプ等の確認が行われている | E8: swebok-v4a.pdf ch01 Software Requirements > 5.2 Simulation and Execution / 5.3 Prototyping | F8: SRC-SWEBOK-V4A | G8: 要原記録確認 | H8: 未記録 | I8: 未記録 | J8: 旧ブックに追加理由・原承認記録なし。原記録の確認が必要。 | K8: 旧ブックの「追加承認」表記を移行。承認者・日付を推測で補完しない。
A9: REQ-906 | B9: 01_要件定義 | C9: 旧ブックで追加承認として登録（カテゴリ: 10. 妥当性確認(SWEBOK 5.1〜5.3)） | D9: プロトタイプ確認の論点が事前定義されていた | E9: swebok-v4a.pdf ch01 Software Requirements > 5.3 Prototyping(cosmetic issues への警告) | F9: SRC-SWEBOK-V4A | G9: 要原記録確認 | H9: 未記録 | I9: 未記録 | J9: 旧ブックに追加理由・原承認記録なし。原記録の確認が必要。 | K9: 旧ブックの「追加承認」表記を移行。承認者・日付を推測で補完しない。
A10: REQ-9901 | B10: 01_要件定義 | C10: 3.4 Addressing Conflict in Requirements(要求間対立の識別と解決) | D10: ステークホルダー間で対立した要求について、解決の経緯と合意記録がある | E10: swebok-v4a.pdf ch01 Software Requirements > 3.4 Addressing Conflict in Requirements(要求間対立の識別と解決) | F10: SRC-SWEBOK-V4A | G10: 要原記録確認 | H10: 未記録 | I10: 未記録 | J10: REQ-201は矛盾の不在を検査するが、SWEBOK 3.4はさらに、対立発見時にエンジニアが単独裁定せずステークホルダー間で交渉して合意し、契約上その決定を顧客まで遡れる形で記録することを求める。解決記録がないと同じ対立が蒸し返され、独断解決が後の紛争になる。 | K10: 旧ブックの「追加承認」表記を移行。承認者・日付を推測で補完しない。
A11: REQ-9902 | B11: 01_要件定義 | C11: 1.5 / 3.2 QoS制約間の相互関係・トレードオフ | D11: QoS制約間のトレードオフ(相互に負の影響を与える組)が検討されている | E11: swebok-v4a.pdf ch01 Software Requirements > 1.5 / 3.2 QoS制約間の相互関係・トレードオフ | F11: SRC-SWEBOK-V4A | G11: 要原記録確認 | H11: 未記録 | I11: 未記録 | J11: SWEBOKは非機能要求の変更時に他への影響を必ず考慮すべきとし、QoS制約間の正負の関係(例: 速度最適化は保守性を下げる)への注意を明示する。個々の数値が妥当でも、組合せとして同時達成不能な非機能要求集合を合意してしまう事故を既存項目は検出できない。 | K11: 旧ブックの「追加承認」表記を移行。承認者・日付を推測で補完しない。
A12: REQ-9903 | B12: 01_要件定義 | C12: 7.6 Requirements Process Quality and Improvement(要求プロセスの品質と改善) | D12: 要求プロセス自体の振り返り・改善の仕組みがある | E12: swebok-v4a.pdf ch01 Software Requirements > 7.6 Requirements Process Quality and Improvement(要求プロセスの品質と改善) | F12: SRC-SWEBOK-V4A | G12: 要原記録確認 | H12: 未記録 | I12: 未記録 | J12: SWEBOK 7.6は要求プロセス自体の計測・ベンチマーク・改善計画を独立トピックとして扱うが、チェックリストは成果物の品質のみを対象とし、プロセスの振り返り・改善の観点が欠けている。プロセス起因の欠陥(獲得不足の常態化等)は成果物検査だけでは再発し続ける。 | K12: 旧ブックの「追加承認」表記を移行。承認者・日付を推測で補完しない。
A13: REQ-9904 | B13: 01_要件定義 | C13: 3.3 Formal Analysis(高インテグリティシステムでの形式的分析) | D13: 高インテグリティ要求に対して形式的仕様・分析の適用が検討されている(該当案件のみ) | E13: swebok-v4a.pdf ch01 Software Requirements > 3.3 Formal Analysis(高インテグリティシステムでの形式的分析) | F13: SRC-SWEBOK-V4A | G13: 要原記録確認 | H13: 未記録 | I13: 未記録 | J13: SWEBOKは高インテグリティ領域では形式的意味論を持つ仕様言語により、デッドロック不在等の性質を静的に証明できる利点を示す。安全性・高信頼性が要求される案件で形式手法の適用可否を検討した形跡がないと、テストでは実証不能な性質が未検証のまま残る。 | K13: 旧ブックの「追加承認」表記を移行。承認者・日付を推測で補完しない。
A14: ARC-901 | B14: 02_アーキテクチャ | C14: 1.3 Uses of Architecture — 再利用・プロダクトライン(共通性と可変性の設計) | D14: 再利用・派生開発における共通性と可変性が設計されている | E14: swebok-v4a.pdf ch02 Software Architecture > 1.3 Uses of Architecture — 再利用・プロダクトライン(共通性と可変性の設計) | F14: SRC-SWEBOK-V4A | G14: 要原記録確認 | H14: 未記録 | I14: 未記録 | J14: SWEBOKはアーキテクチャの主要用途として、共通性の識別と可変性に対応した再利用可能コンポーネントの設計によるプログラムファミリー/ソフトウェアプロダクトラインの基盤形成を挙げているが、チェックリストには再利用・派生開発の観点がない。複数製品・複数環境への展開が想定される場合、共通/可変の設計を怠るとコピー派生が乱立し保守コストが倍増する。 | K14: 旧ブックの「追加承認」表記を移行。承認者・日付を推測で補完しない。
... A68: SEC-954 | B68: 13_セキュリティ | C68: 旧ブックで追加承認として登録（カテゴリ: 11. ドキュメント品質・トレーサビリティ(SEC-951〜)） | D68: 文書に改訂履歴と承認状態があり、機微情報を含まない | E68: swebok-v4a.pdf ch13 Software Security > 2.2 ISMS(文書化された計画)/ 実務補完(文書管理) | F68: SRC-SWEBOK-V4A;SRC-PRACTICE | G68: 要原記録確認 | H68: 未記録 | I68: 未記録 | J68: 旧ブックに追加理由・原承認記録なし。原記録の確認が必要。 | K68: 旧ブックの「追加承認」表記を移行。承認者・日付を推測で補完しない。

Sheet 01_要件定義
A1: ID | B1: 区分 | C1: カテゴリ | D1: 基準重要度 | E1: チェック項目 | F1: 合格基準 | G1: 意図(なぜ確認するか) | H1: 対象ドキュメント(参照箇所) | I1: 適用プロファイル | J1: 適用条件 | K1: 出典ID | L1: 重複統制グループ | M1: 案件重要度 | N1: 適用判定 | O1: 判定 | P1: 証跡・参照箇所 | Q1: 指摘・Issue ID | R1: 対応方針 | S1: 例外・リスク受容承認者 | T1: 是正期限 | U1: レビュアー | V1: レビュー日 | W1: 再確認結果
A2: REQ-001 | B2: SWEBOK | C2: 1. 文書構成・全体(SWEBOK 1章全般 / ISO 29148) | D2: Critical | E2: すべての要求に一意IDが付与されている | F2: 全要求文にIDがあり、文書全体でIDの重複・欠番の未管理がない | G2: IDのない要求はトレース・変更管理・テスト対応付けの起点を持てず、変更漏れや検証漏れが下流で静かに発生する。SWEBOKが要求管理の前提とする「個々の要求の構成管理」を成立させるための最低条件。 | H2: swebok-v4a.pdf ch01 Software Requirements > 4.5 Additional Attributes of Requirements(tag)/ 実務補完(ISO/IEC/IEEE 29148) | I2: CORE | J2: 原則適用。案件スコープ・成果物・規制・リスク上非該当の場合はN/A根拠を記録。 | K2: SRC-SWEBOK-V4A;SRC-ISO-29148;SRC-PRACTICE
A3: REQ-002 | B3: SWEBOK | C3: 1. 文書構成・全体(SWEBOK 1章全般 / ISO 29148) | D3: High | E3: 文書の目的・スコープ・対象読者が冒頭に記載されている | F3: 「はじめに」相当の節に目的・スコープ・対象読者の3点が明記されている | G3: SWEBOKは要求文書の意思決定を読者分析(audience analysis)に基づかせることを最重要推奨とする。目的・スコープ・読者が曖昧な文書は、スコープ外要望の混入や読者に届かない記述粒度を招く。 | H3: swebok-v4a.pdf ch01 Software Requirements > 4. Requirements Specification(audience analysis) | I3: CORE | J3: 原則適用。案件スコープ・成果物・規制・リスク上非該当の場合はN/A根拠を記録。 | K3: SRC-SWEBOK-V4A
A4: REQ-003 | B4: SWEBOK | C4: 1. 文書構成・全体(SWEBOK 1章全般 / ISO 29148) | D4: High | E4: 用語集または用語定義があり、ドメイン用語・略語が定義されている | F4: 本文で使われる略語・ドメイン固有語が用語集で引ける(未定義の略語が本文にない) | G4: SWEBOKが挙げる二大問題の一つ「曖昧性(複数解釈の余地)」の多くは用語の未定義に起因する。ドメイン用語の解釈違いは設計・テストまで波及して指数的な手戻りを生む。 | H4: swebok-v4a.pdf ch01 Software Requirements > 3.1 Basic Requirements Analysis(unambiguous)/ 実務補完(ISO 29148) | I4: CORE | J4: 原則適用。案件スコープ・成果物・規制・リスク上非該当の場合はN/A根拠を記録。 | K4: SRC-SWEBOK-V4A;SRC-ISO-29148;SRC-PRACTICE
A5: REQ-004 | B5: SWEBOK | C5: 1. 文書構成・全体(SWEBOK 1章全般 / ISO 29148) | D5: High | E5: 拘束力を示す語(shall/must/should/may 等)の使い分けが定義され、一貫して使われている | F5: 規約の定義節があり、本文の要求文がその規約に従っている | G5: 拘束力語の使い分けが不定だと、努力目標を必須要求と誤解して過剰実装したり、必須要求を任意と誤解して欠落させたりする。要求が「binding(拘束的)」であるかの判定基盤になる。 | H5: swebok-v4a.pdf ch01 Software Requirements > 3.1 Basic Requirements Analysis(binding)/ 実務補完(ISO 29148, RFC 2119) | I5: CORE | J5: 原則適用。案件スコープ・成果物・規制・リスク上非該当の場合はN/A根拠を記録。 | K5: SRC-SWEBOK-V4A;SRC-ISO-29148;SRC-RFC;SRC-PRACTICE
A6: REQ-005 | B6: SWEBOK | C6: 1. 文書構成・全体(SWEBOK 1章全般 / ISO 29148) | D6: Medium | E6: 参照文書(上位計画書、RFP、法令、標準)が版数付きで列挙されている | F6: 参照文書一覧に文書名と版数(または日付)がある | G6: SWEBOKは要求の後方トレース先として上位文書・標準・規制を挙げる。参照文書の版が不明だと外部一貫性の検証基準が動き、どの版と整合させたのかが変更時に再現できない。 | H6: swebok-v4a.pdf ch01 Software Requirements > 7.3 Requirements Tracing / 2.1 Requirements Sources(非人間源泉) | I6: CORE | J6: 原則適用。案件スコープ・成果物・規制・リスク上非該当の場合はN/A根拠を記録。 | K6: SRC-SWEBOK-V4A
A7: REQ-006 | B7: SWEBOK | C7: 1. 文書構成・全体(SWEBOK 1章全般 / ISO 29148) | D7: Medium | E7: 増分的仕様か包括的仕様かの方針が明記されている | F7: 差分記述か全量記述かが文書内に宣言され、実際の記述方式と一致している | G7: 増分仕様か包括仕様かが宣言されていないと、読者が「書かれていない要求は廃止されたのか前版有効なのか」を判断できず、廃止済み要求の実装や有効要求の欠落を招く。 | H7: swebok-v4a.pdf ch01 Software Requirements > 4.6 Incremental and Comprehensive Requirements Specification | I7: CORE | J7: 原則適用。案件スコープ・成果物・規制・リスク上非該当の場合はN/A根拠を記録。 | K7: SRC-SWEBOK-V4A
A8: REQ-007 | B8: SWEBOK | C8: 1. 文書構成・全体(SWEBOK 1章全般 / ISO 29148) | D8: Medium | E8: 未決事項(TBD/TBR)が識別子付きで一覧管理され、解決期限か担当が付いている | F8: TBDが本文に散在するだけでなく一覧化され、各件に担当または期限がある | G8: SWEBOKの言う「不完全性」問題の管理装置。TBDが本文に散在したまま放置されると、未決のまま設計・実装が進み、後工程での判明時に指数的な手戻りコストになる。 | H8: swebok-v4a.pdf ch01 Software Requirements > 3.1 Basic Requirements Analysis(complete)/ 実務補完(ISO 29148) | I8: CORE | J8: 原則適用。案件スコープ・成果物・規制・リスク上非該当の場合はN/A根拠を記録。 | K8: SRC-SWEBOK-V4A;SRC-ISO-29148;SRC-PRACTICE
A9: REQ-008 | B9: SWEBOK | C9: 1. 文書構成・全体(SWEBOK 1章全般 / ISO 29148) | D9: Low | E9: 変更履歴(版数・日付・変更者・変更概要)がある | F9: 変更履歴表が存在し、最新版の記録がある | G9: 要求文書は他の成果物と同様に構成管理の対象であるべきというSWEBOKの原則の最小形。履歴がないと、レビューや承認がどの版に対して行われたかを事後に特定できない。 | H9: swebok-v4a.pdf ch01 Software Requirements > 4. Requirements Specification(構成管理)/ 6.2 Requirements Change Control | I9: CORE | J9: 原則適用。案件スコープ・成果物・規制・リスク上非該当の場合はN/A根拠を記録。 | K9: SRC-SWEBOK-V4A
A10: REQ-101 | B10: SWEBOK | C10: 2. 個々の要求の記述品質(SWEBOK 3.1) | D10: Critical | E10: 要求文に曖昧語がない | F10: 「など」「等」「適切に」「可能な限り」「柔軟に」「高速に」「使いやすい」等の検証不能語が要求文(shall文)に含まれない。含む場合は数値・列挙・条件で具体化されている | G10: SWEBOKが実プロジェクトの二大要求問題の一つに挙げる「曖昧性」への直接の防御。曖昧語は複数解釈のうち誤った1つで実装される欠陥の温床であり、受入時の紛争原因にもなる。 | H10: swebok-v4a.pdf ch01 Software Requirements > 3.1 Basic Requirements Analysis(unambiguous) | I10: CORE | J10: 原則適用。案件スコープ・成果物・規制・リスク上非該当の場合はN/A根拠を記録。 | K10: SRC-SWEBOK-V4A
A11: REQ-102 | B11: SWEBOK | C11: 2. 個々の要求の記述品質(SWEBOK 3.1) | D11: Critical | E11: 各要求がテスト可能である | F11: 各要求について検証方法(テスト・検査・分析・デモのいずれか)が記載されているか、合否判定手順を第三者が書ける程度に具体的である | G11: テスト不能な要求は合否を客観的に示せず、実装完了の判定が主観論争になる。SWEBOKは「準拠・非準拠を明確に実証できる(testable/quantified)」ことを要求の望ましい性質として明示する。 | H11: swebok-v4a.pdf ch01 Software Requirements > 3.1 Basic Requirements Analysis(testable) | I11: CORE | J11: 原則適用。案件スコープ・成果物・規制・リスク上非該当の場合はN/A根拠を記録。 | K11: SRC-SWEBOK-V4A
A12: REQ-103 | B12: SWEBOK | C12: 2. 個々の要求の記述品質(SWEBOK 3.1) | D12: Critical | E12: 各要求が原子的である(1要求1事項) | F12: 1つの要求文に独立に検証すべき事項が2つ以上含まれない(「および」「かつ」で複数の別個の振る舞いを連結していない) | G12: 複数事項を束ねた要求は一部実装・一部未実装の状態を表現できず、トレースや優先順位付けの単位が壊れる。SWEBOKは「atomic(単一の決定を表す)」を望ましい性質に挙げる。 | H12: swebok-v4a.pdf ch01 Software Requirements > 3.1 Basic Requirements Analysis(atomic) | I12: CORE | J12: 原則適用。案件スコープ・成果物・規制・リスク上非該当の場合はN/A根拠を記録。 | K12: SRC-SWEBOK-V4A
A13: REQ-104 | B13: SWEBOK | C13: 2. 個々の要求の記述品質(SWEBOK 3.1) | D13: High | E13: 要求が解決手段でなく必要性(真のニーズ)を表している | F13: 実装手段の指定(特定ライブラリ・アルゴリズム等)が、意図的な技術制約として根拠付きで書かれている場合を除き要求文に現れない | G13: 手段として語られた要望をそのまま要求化すると、真の問題を解かない次善解を実装するリスクがある(SWEBOKが5-whysで警告する点)。設計の自由度も不必要に奪われる。 | H13: swebok-v4a.pdf ch01 Software Requirements > 3.1 Basic Requirements Analysis(represent true stakeholder needs / 5-whys) | I13: CORE | J13: 原則適用。案件スコープ・成果物・規制・リスク上非該当の場合はN/A根拠を記録。 | K13: SRC-SWEBOK-V4A
... A75: REQ-1004 | B75: SWEBOK | C75: 11. 要求管理・変更管理(SWEBOK 6.1〜6.3) | D75: Medium | E75: 要求スクラビングが実施されている | F75: スコープ外・低価値として除外した要求の一覧と除外理由が残っている(除外ゼロの場合はスクラビング実施の記録がある) | G75: SWEBOKのスクラビングは「ステークホルダーニーズを満たす最小の要求集合」を見つけて解の規模・コストを最小化する活動。実施しないとスコープ外・低ROIの要求が温存され、工数と納期を静かに侵食する。 | H75: swebok-v4a.pdf ch01 Software Requirements > 6.1 Requirements Scrubbing | I75: CORE | J75: 原則適用。案件スコープ・成果物・規制・リスク上非該当の場合はN/A根拠を記録。 | K75: SRC-SWEBOK-V4A
A76: REQ-1005 | B76: SWEBOK | C76: 11. 要求管理・変更管理(SWEBOK 6.1〜6.3) | D76: Medium | E76: スコープと制約(コスト・期間・要員)の整合が確認されている | F76: 要求規模(件数・ファンクショナルサイズ・ストーリーポイント等)と制約の突合記録があり、超過時の調整判断が記録されている | G76: SWEBOKのスコープマッチングに対応。要求スコープが制約を超えたまま進むと、破綻が開発後半に露見して最悪のタイミングでの削減交渉になる。定量的(機能規模単位)な突合が望ましいとされる。 | H76: swebok-v4a.pdf ch01 Software Requirements > 6.3 Scope Matching | I76: CORE | J76: 原則適用。案件スコープ・成果物・規制・リスク上非該当の場合はN/A根拠を記録。 | K76: SRC-SWEBOK-V4A | L76: COST
A77: REQ-1006 | B77: SWEBOK | C77: 11. 要求管理・変更管理(SWEBOK 6.1〜6.3) | D77: Low | E77: 要求ごとの安定性(変動しやすさ)が評価されている | F77: 変動リスクの高い要求に安定性属性または注記が付いている | G77: SWEBOKは変動しやすい要求の識別が「変更に強い設計」の確立を助けるとする。安定性評価がないと、変動必至の要求を硬直した構造で実装し、変更のたびに大規模改修を強いられる。 | H77: swebok-v4a.pdf ch01 Software Requirements > 7.4 Requirements Stability and Volatility | I77: CORE | J77: 原則適用。案件スコープ・成果物・規制・リスク上非該当の場合はN/A根拠を記録。 | K77: SRC-SWEBOK-V4A
A78: REQ-1101 | B78: SWEBOK | C78: 12. 優先順位付け・トレーサビリティ・計測(SWEBOK 7.2〜7.5) | D78: Critical | E78: RTMが存在し、要求⇔テストの対応が記録されている | F78: 承認済み要求の各行にテストケースID(または検証手段)が対応付いているか、対応付け予定が管理されている | G78: SWEBOKはトレーシングの第一の目的を成果物間の整合の検証に置く。要求⇔テストの対応がないと、検証されない要求(実装漏れの見逃し)と要求のないテスト(仕様の欠落か無駄)を検出できない。 | H78: swebok-v4a.pdf ch01 Software Requirements > 7.3 Requirements Tracing(forward to test cases) | I78: CORE | J78: 原則適用。案件スコープ・成果物・規制・リスク上非該当の場合はN/A根拠を記録。 | K78: SRC-SWEBOK-V4A
A79: REQ-1102 | B79: SWEBOK | C79: 12. 優先順位付け・トレーサビリティ・計測(SWEBOK 7.2〜7.5) | D79: Critical | E79: 全要求が上位要求・ビジネス目標にトレースされる(後方トレース) | F79: RTM上で源泉・上位目標が空欄の承認済み要求がない | G79: 上位にトレースできない要求は「存在理由を説明できない要求」であり、スコープクリープの典型的な侵入形態。SWEBOKは源泉文書への後方トレースを明示する。 | H79: swebok-v4a.pdf ch01 Software Requirements > 7.3 Requirements Tracing(back to source documentation) | I79: CORE | J79: 原則適用。案件スコープ・成果物・規制・リスク上非該当の場合はN/A根拠を記録。 | K79: SRC-SWEBOK-V4A | L79: OPS-OBSERVABILITY
A80: REQ-1103 | B80: SWEBOK | C80: 12. 優先順位付け・トレーサビリティ・計測(SWEBOK 7.2〜7.5) | D80: High | E80: 上位要求から下位要求への前方トレースが取れる | F80: ビジネス目標・システム要求の各項目が、少なくとも1つのソフトウェア要求に展開されているか、未展開が識別されている | G80: SWEBOKのトレーシング設問「各要求に対応する下位要素があるか」の適用。前方トレースの欠落は上位目標の未実現(要求の不完全性)をリリースまで隠す。 | H80: swebok-v4a.pdf ch01 Software Requirements > 7.3 Requirements Tracing(forward tracing) | I80: CORE | J80: 原則適用。案件スコープ・成果物・規制・リスク上非該当の場合はN/A根拠を記録。 | K80: SRC-SWEBOK-V4A | L80: OPS-OBSERVABILITY
A81: REQ-1104 | B81: SWEBOK | C81: 12. 優先順位付け・トレーサビリティ・計測(SWEBOK 7.2〜7.5) | D81: High | E81: すべての要求に優先度が付与され、差が付いている | F81: 優先度属性の空欄がなく、全件が同一優先度になっていない | G81: SWEBOKは優先順位付けが価値の高い機能の早期提供・対立解消・スコープマッチングを支えるとする。全件同一優先度は優先順位付けの放棄であり、削減交渉時に判断材料がなくなる。 | H81: swebok-v4a.pdf ch01 Software Requirements > 7.2 Requirements Prioritization | I81: CORE | J81: 原則適用。案件スコープ・成果物・規制・リスク上非該当の場合はN/A根拠を記録。 | K81: SRC-SWEBOK-V4A
A82: REQ-1105 | B82: SWEBOK | C82: 12. 優先順位付け・トレーサビリティ・計測(SWEBOK 7.2〜7.5) | D82: Medium | E82: 優先順位付けの基準が定義されている | F82: 価値・コスト・リスク・不満足度(Kanoモデル等)のうち何を基準にしたかが記録されている | G82: SWEBOKは満足度だけでなく「なければどれほど不満か」(Kanoモデル)まで考慮しないと誤った優先順位になると警告する。基準の記録がないと優先度が声の大きさで決まり、必須機能が後回しになる。 | H82: swebok-v4a.pdf ch01 Software Requirements > 7.2 Requirements Prioritization(価値・コスト・リスク・Kanoモデル) | I82: CORE | J82: 原則適用。案件スコープ・成果物・規制・リスク上非該当の場合はN/A根拠を記録。 | K82: SRC-SWEBOK-V4A
A83: REQ-1106 | B83: SWEBOK | C83: 12. 優先順位付け・トレーサビリティ・計測(SWEBOK 7.2〜7.5) | D83: Medium | E83: 要求の規模・件数が計測されている | F83: 要求件数、ファンクショナルサイズまたはストーリーポイント合計が記録されている | G83: SWEBOKは要求の量(機能規模・ストーリーポイント)が開発規模の評価・見積り・他計測の分母として有用とする。計測がないとスコープマッチングも変更規模の定量化もできない。 | H83: swebok-v4a.pdf ch01 Software Requirements > 7.5 Measuring Requirements(FSM, story points) | I83: CORE | J83: 原則適用。案件スコープ・成果物・規制・リスク上非該当の場合はN/A根拠を記録。 | K83: SRC-SWEBOK-V4A
A84: REQ-1107 | B84: SWEBOK | C84: 12. 優先順位付け・トレーサビリティ・計測(SWEBOK 7.2〜7.5) | D84: Medium | E84: RTMの状態列が運用されている | F84: 各要求の状態(提案/承認/実装済み/検証済み等)が定義された値集合で管理されている | G84: SWEBOKはマネジメントが要求の状態からプロジェクト完了度を評価できると述べる。状態列が運用されていないRTMは作成時点のスナップショットに過ぎず、進捗・検証状況の把握手段にならない。 | H84: swebok-v4a.pdf ch01 Software Requirements > 4.5(属性)/ 序論(要求の状態によるプロジェクト完了評価) | I84: CORE | J84: 原則適用。案件スコープ・成果物・規制・リスク上非該当の場合はN/A根拠を記録。 | K84: SRC-SWEBOK-V4A
A85: REQ-1108 | B85: SWEBOK | C85: 12. 優先順位付け・トレーサビリティ・計測(SWEBOK 7.2〜7.5) | D85: Low | E85: 要求変更率(volatility)が追跡されている | F85: ベースライン後の変更件数・変更率の記録または集計手段がある | G85: SWEBOKは要求の安定性・変動性の評価を実務上の考慮事項とする。変更率の追跡は、要求プロセスの品質問題(獲得不足・合意の脆さ)の早期警報であり、再見積りの根拠にもなる。 | H85: swebok-v4a.pdf ch01 Software Requirements > 7.4 Requirements Stability and Volatility / 7.5 Measuring Requirements | I85: CORE | J85: 原則適用。案件スコープ・成果物・規制・リスク上非該当の場合はN/A根拠を記録。 | K85: SRC-SWEBOK-V4A
A86: REQ-1201 | B86: SWEBOK | C86: 13. ツール・運用(SWEBOK 8章) | D86: Medium | E86: 要求の管理媒体・ツールが特定され関係者に共有されている | F86: 要求の正本がどこにあるか(ツール名・リポジトリ・文書)が文書化され、複数の正本が併存していない | G86: 正本が複数併存すると、どれを見て実装・テストするかが人によって分かれ、古い版に基づく作業が発生する。SWEBOKは要求管理ツールの役割(属性保存・トレース・変更管理)を明示し、正本の一元化を前提とする。 | H86: swebok-v4a.pdf ch01 Software Requirements > 8.1 Requirements Management Tools | I86: CORE | J86: 原則適用。案件スコープ・成果物・規制・リスク上非該当の場合はN/A根拠を記録。 | K86: SRC-SWEBOK-V4A
A87: REQ-1202 | B87: SWEBOK | C87: 13. ツール・運用(SWEBOK 8章) | D87: Medium | E87: 要求規模に対して管理方法が持続可能である | F87: 要求数百件超・高変更頻度の案件で手作業スプレッドシート運用の場合、属性管理・トレース更新の運用手順が定義されているか、ツール導入の検討記録がある | G87: SWEBOKは「トレースと変更管理はツール支援があって初めて実用的になり得る」とし、スプレッドシート等のアドホック管理を「満足度の低い方法」と明言する。規模に対して手作業運用が破綻すると、トレース・属性が更新されず形骸化する。 | H87: swebok-v4a.pdf ch01 Software Requirements > 8.1 Requirements Management Tools(ad hoc管理への警告) | I87: CORE | J87: 原則適用。案件スコープ・成果物・規制・リスク上非該当の場合はN/A根拠を記録。 | K87: SRC-SWEBOK-V4A
A88: REQ-1203 | B88: SWEBOK | C88: 13. ツール・運用(SWEBOK 8章) | D88: Low | E88: 仕様からテストケースを導出する方針が定義されている | F88: 受入基準・デシジョンテーブル・モデル等からのテストケース導出方法がテスト計画側と合意されている | G88: SWEBOKは形式性の高い仕様(BDDシナリオ・状態モデル等)ほどテストケースを機械的に導出できるとする。導出方針をテスト側と事前合意しないと、仕様化技法の選択がテスト工程で活かされず二重作業になる。 | H88: swebok-v4a.pdf ch01 Software Requirements > 8.3 Functional Test Case Generation Tools / 4.3(BDDシナリオからのテスト導出) | I88: CORE | J88: 原則適用。案件スコープ・成果物・規制・リスク上非該当の場合はN/A根拠を記録。 | K88: SRC-SWEBOK-V4A
A89: REQ-9903 | B89: 追加承認 | C89: 13. ツール・運用(SWEBOK 8章) | D89: Low | E89: 要求プロセス自体の振り返り・改善の仕組みがある | F89: 要求起因の欠陥・変更の傾向を振り返る場(工程完了時レビュー、レトロスペクティブ等)が計画され、実施記録または改善アクションが残っている | G89: 要求起因の欠陥はプロセスの欠陥の症状であり、成果物検査だけでは同種の欠陥が案件のたびに再発する。プロセス改善のループを確認する。 | H89: swebok-v4a.pdf ch01 Software Requirements > 7.6 Requirements Process Quality and Improvement(要求プロセスの品質と改善) | I89: CORE | J89: 原則適用。案件スコープ・成果物・規制・リスク上非該当の場合はN/A根拠を記録。 | K89: SRC-SWEBOK-V4A

Sheet 02_アーキテクチャ
A1: ID | B1: 区分 | C1: カテゴリ | D1: 基準重要度 | E1: チェック項目 | F1: 合格基準 | G1: 意図(なぜ確認するか) | H1: 対象ドキュメント(参照箇所) | I1: 適用プロファイル | J1: 適用条件 | K1: 出典ID | L1: 重複統制グループ | M1: 案件重要度 | N1: 適用判定 | O1: 判定 | P1: 証跡・参照箇所 | Q1: 指摘・Issue ID | R1: 対応方針 | S1: 例外・リスク受容承認者 | T1: 是正期限 | U1: レビュアー | V1: レビュー日 | W1: 再確認結果
A2: ARC-001 | B2: SWEBOK | C2: 1. コンテキストとステークホルダー | D2: Critical | E2: ステークホルダーが特定されている | F2: 利用者・開発者・運用者・保守者を含む主要ステークホルダーが一覧化され、各々に少なくとも1つの関心事が対応付けられている | G2: 誰の関心事に応えるアーキテクチャかが不明だと、声の大きい一部の利害だけを反映した設計になり、運用者・保守者の要求が後工程で噴出して大規模な手戻りを招く。 | H2: swebok-v4a.pdf ch02 Software Architecture > 1.2 Stakeholders and Concerns | I2: CORE | J2: 原則適用。案件スコープ・成果物・規制・リスク上非該当の場合はN/A根拠を記録。 | K2: SRC-SWEBOK-V4A
A3: ARC-002 | B3: SWEBOK | C3: 1. コンテキストとステークホルダー | D3: Critical | E3: ステークホルダーの関心事が文書化されている | F3: 関心事が機能・非機能(品質属性)・制約のいずれかに分類され、一覧表または同等の形式で記録されている | G3: 関心事を分類・記録しないと非機能や制約が暗黙のまま設計が進み、後から性能・セキュリティ要求が判明して構造の作り直しが発生する。 | H3: swebok-v4a.pdf ch02 Software Architecture > 1.2 Stakeholders and Concerns(関心事の機能/非機能/制約への分類) | I3: CORE | J3: 原則適用。案件スコープ・成果物・規制・リスク上非該当の場合はN/A根拠を記録。 | K3: SRC-SWEBOK-V4A
A4: ARC-003 | B4: SWEBOK | C4: 1. コンテキストとステークホルダー | D4: High | E4: システムコンテキストが記述されている | F4: 外部システム・利用者・環境との境界と相互作用がコンテキスト図または文章で示され、システムの責務範囲が判別できる | G4: アーキテクチャは環境の中のシステムを外向きに捉えるものであり、境界が曖昧だと責務の押し付け合いや外部システム連携の設計漏れが起きる。 | H4: swebok-v4a.pdf ch02 Software Architecture > 1.1 The Senses of "Architecture"(環境の中のシステムという定義) | I4: CORE | J4: 原則適用。案件スコープ・成果物・規制・リスク上非該当の場合はN/A根拠を記録。 | K4: SRC-SWEBOK-V4A
A5: ARC-004 | B5: SWEBOK | C5: 1. コンテキストとステークホルダー | D5: High | E5: 関心事とビュー/ADRの対応が示されている | F5: 各関心事について、それを扱うビューまたはADRへの対応(トレーサビリティ)が確認できる。どこにも扱われない関心事がない | G5: 関心事とビュー/決定の対応が取れていないと、どこにも扱われない関心事が放置され、レビューでも見落とされたままリリースに至る。 | H5: swebok-v4a.pdf ch02 Software Architecture > 2. Software Architecture Description / 2.1 Architecture Views and Viewpoints | I5: CORE | J5: 原則適用。案件スコープ・成果物・規制・リスク上非該当の場合はN/A根拠を記録。 | K5: SRC-SWEBOK-V4A | L5: CONTINUITY-DR
A6: ARC-005 | B6: SWEBOK | C6: 1. コンテキストとステークホルダー | D6: Medium | E6: 運用・保守・テストの関心事が含まれている | F6: 開発時の関心事だけでなく、展開・運用・監視・保守・テスト容易性に関する関心事が少なくとも1つ以上記載されている | G6: 関心事は開発・運用・保守・テストなど広範な影響を含むため、開発時の視点だけで設計すると運用不能・テスト困難なシステムが本番で発覚する。 | H6: swebok-v4a.pdf ch02 Software Architecture > 1.2 Stakeholders and Concerns(developmental/operationalを含む関心事の範囲) | I6: CORE | J6: 原則適用。案件スコープ・成果物・規制・リスク上非該当の場合はN/A根拠を記録。 | K6: SRC-SWEBOK-V4A
A7: ARC-006 | B7: SWEBOK | C7: 1. コンテキストとステークホルダー | D7: Medium | E7: 組織構造が考慮されている | F7: チーム編成・組織間の責任分界とコンポーネント境界の関係(コンウェイの法則への言及または整合性の検討)が記録されている | G7: コンウェイの法則によりアーキテクチャは組織の通信構造を写し取るため、組織と構造の不整合を放置するとチーム間調整コストの爆発や責任の空白地帯を生む。 | H7: swebok-v4a.pdf ch02 Software Architecture > 1.3 Uses of Architecture(Conway's Law) | I7: CORE | J7: 原則適用。案件スコープ・成果物・規制・リスク上非該当の場合はN/A根拠を記録。 | K7: SRC-SWEBOK-V4A
A8: ARC-007 | B8: SWEBOK | C8: 1. コンテキストとステークホルダー | D8: Low | E8: 関心事の将来変化が考慮されている | F8: 事業環境・規制・技術動向による関心事の変化(例: 持続可能性、エネルギー効率)への言及または見直し方針がある | G8: 関心事は静的でなくライフサイクルや技術・政策の変化とともに進化するため、見直し観点がないと規制変更やエネルギー効率要求に構造が追随できなくなる。 | H8: swebok-v4a.pdf ch02 Software Architecture > 1.2 Stakeholders and Concerns(関心事の進化、持続可能性への言及) | I8: CORE | J8: 原則適用。案件スコープ・成果物・規制・リスク上非該当の場合はN/A根拠を記録。 | K8: SRC-SWEBOK-V4A
A9: ARC-903 | B9: 追加承認 | C9: 1. コンテキストとステークホルダー | D9: Medium | E9: 開発アプローチに応じたアーキテクチャ活動の位置付けが定義されている | F9: 採用する開発アプローチ(ウォーターフォール/アジャイル/プロダクトライン等)の中で、アーキテクチャの分析・統合・評価をいつ・どの程度行うかが定められている。アジャイルで創発的アーキテクチャに依る場合、ユーザーストーリーに現れない重要品質特性(安全性・性能等)の扱いが別途定義されている | G9: アジャイルで創発任せにすると、ユーザーストーリーに現れない安全性・性能などの重要特性が誰にも設計されず、後から構造レベルの作り直しが必要になる。 | H9: swebok-v4a.pdf ch02 Software Architecture > 3.1 Architecture in Context — ライフサイクルコンテキスト(アジャイル等での創発的アーキテクチャのリスク) | I9: CORE | J9: 原則適用。案件スコープ・成果物・規制・リスク上非該当の場合はN/A根拠を記録。 | K9: SRC-SWEBOK-V4A
A10: ARC-010 | B10: SWEBOK | C10: 2. アーキテクチャ上重要な要求(ASR) | D10: Critical | E10: ASRが識別されている | F10: アーキテクチャ上重要な要求が一般要求と区別して一覧化され、各ASRに識別子が付与されている | G10: ASRを一般要求と区別しないと、アーキテクチャを左右する要求が後工程に先送りされ、構造を壊さないと満たせない要求が実装後に見つかる。 | H10: swebok-v4a.pdf ch02 Software Architecture > 3.2.1 Architecture Analysis(ASRの収集と定式化) | I10: CORE | J10: 原則適用。案件スコープ・成果物・規制・リスク上非該当の場合はN/A根拠を記録。 | K10: SRC-SWEBOK-V4A
A11: ARC-011 | B11: SWEBOK | C11: 2. アーキテクチャ上重要な要求(ASR) | D11: Critical | E11: ASRの選定基準が妥当である | F11: 各ASRについて、変更困難性・高コスト・横断性・品質属性への直結のいずれかの根拠が説明されている、または選定基準が文書化されている | G11: 選定基準がないとASRの認定が恣意的になり、重要でない要求に設計労力を割く一方で真に構造を制約する要求を見落とす。 | H11: swebok-v4a.pdf ch02 Software Architecture > 3.2.1 Architecture Analysis(ASR=アーキテクチャに影響する要求の定義) | I11: CORE | J11: 原則適用。案件スコープ・成果物・規制・リスク上非該当の場合はN/A根拠を記録。 | K11: SRC-SWEBOK-V4A
A12: ARC-012 | B12: SWEBOK | C12: 2. アーキテクチャ上重要な要求(ASR) | D12: High | E12: ASRに優先度が付与されている | F12: 全ASRに優先度(高/中/低または同等の尺度)が付与され、優先度の判断基準が記載されている | G12: 全要求を同等に扱うと分析・統合の反復で焦点が定まらず、コストや納期との衝突時にどの要求を交渉・緩和すべきか判断できない。 | H12: swebok-v4a.pdf ch02 Software Architecture > 3.2.1 Architecture Analysis(要求と制約の衝突時の交渉) | I12: CORE | J12: 原則適用。案件スコープ・成果物・規制・リスク上非該当の場合はN/A根拠を記録。 | K12: SRC-SWEBOK-V4A
A13: ARC-013 | B13: SWEBOK | C13: 2. アーキテクチャ上重要な要求(ASR) | D13: Critical | E13: 優先度の高いASRすべてに対応方針がある | F13: 優先度「高」の各ASRについて、それを満たすアーキテクチャ上の対応(スタイル・戦術・構造)がADまたはADRで特定できる | G13: 高優先ASRに対応する構造・戦術が特定できないと、要求が「書かれただけ」で終わり、評価時に充足性を検証する手がかりも失われる。 | H13: swebok-v4a.pdf ch02 Software Architecture > 3.2.2 Architecture Synthesis(ASRが示す設計問題への解の展開) | I13: CORE | J13: 原則適用。案件スコープ・成果物・規制・リスク上非該当の場合はN/A根拠を記録。 | K13: SRC-SWEBOK-V4A
A14: ARC-014 | B14: SWEBOK | C14: 2. アーキテクチャ上重要な要求(ASR) | D14: High | E14: ASRと要求文書のトレーサビリティがある | F14: 各ASRが元の要求(要求仕様書の項番等)まで遡れる。出典のないASRがない | G14: 出典不明のASRは根拠の検証も変更時の影響分析もできず、要求変更がアーキテクチャへ伝播しない(またはその逆)事故を招く。 | H14: swebok-v4a.pdf ch02 Software Architecture > 3.2.1 Architecture Analysis(既知の要求・コンテキストに基づく分析) | I14: CORE | J14: 原則適用。案件スコープ・成果物・規制・リスク上非該当の場合はN/A根拠を記録。 | K14: SRC-SWEBOK-V4A
A15: ARC-015 | B15: SWEBOK | C15: 2. アーキテクチャ上重要な要求(ASR) | D15: Medium | E15: 非機能要求がISO/IEC 25010等の品質モデルに対応付けられている | F15: 品質属性が標準の品質特性分類(性能効率性・信頼性・セキュリティ・保守性等)で整理されている | G15: 品質属性を標準分類で整理しないと、関係者ごとに用語の解釈がずれ、性能とスケーラビリティの混同のような認識齟齬が評価段階まで残る。 | H15: swebok-v4a.pdf ch02 Software Architecture > 1.2 Stakeholders and Concerns(品質属性としての関心事)+ 実務補完(ISO/IEC 25010) | I15: CORE | J15: 原則適用。案件スコープ・成果物・規制・リスク上非該当の場合はN/A根拠を記録。 | K15: SRC-SWEBOK-V4A;SRC-ISO-25010;SRC-PRACTICE
A16: ARC-020 | B16: SWEBOK | C16: 3. 制約と前提条件 | D16: High | E16: 技術的制約が明記されている | F16: 既存資産・利用必須の技術・上位アーキテクチャ(EA/リファレンスアーキテクチャ)からの制約が列挙されている | G16: エンタープライズアーキテクチャや上位システムからの制約はASRとして反映すべきものであり、見落とすと適合性検査や統合段階で不適合が発覚し設計をやり直すことになる。 | H16: swebok-v4a.pdf ch02 Software Architecture > 3.1 Architecture in Context / 3.4 Architecting in the Large(上位アーキテクチャへの準拠) | I16: CORE | J16: 原則適用。案件スコープ・成果物・規制・リスク上非該当の場合はN/A根拠を記録。 | K16: SRC-SWEBOK-V4A
A17: ARC-021 | B17: SWEBOK | C17: 3. 制約と前提条件 | D17: High | E17: 組織的・事業的制約が明記されている | F17: 予算・納期・チームスキル・調達方針など、設計の選択肢を狭める非技術的制約が記録されている | G17: 予算・納期・スキルなどの事業的制約は設計の選択肢を実質的に決めるため、無視すると技術的には正しくても実現不能な机上の設計になる。 | H17: swebok-v4a.pdf ch02 Software Architecture > 1.2 Stakeholders and Concerns(business/organizational/economicな影響) | I17: CORE | J17: 原則適用。案件スコープ・成果物・規制・リスク上非該当の場合はN/A根拠を記録。 | K17: SRC-SWEBOK-V4A
... A20: ARC-024 | B20: SWEBOK | C20: 3. 制約と前提条件 | D20: Low | E20: 前提が崩れた場合の影響が検討されている | F20: 主要な前提条件について、成立しなくなった場合の影響または見直しトリガーが記載されている | G20: 前提が崩れたときの影響と見直しトリガーがないと、環境変化に誰も気づかず、破綻した前提の上に機能追加を積み重ねてしまう。 | H20: swebok-v4a.pdf ch02 Software Architecture > 2.4 Architecture as Significant Decisions(条件変化時の決定の再検討) | I20: CORE | J20: 原則適用。案件スコープ・成果物・規制・リスク上非該当の場合はN/A根拠を記録。 | K20: SRC-SWEBOK-V4A;SRC-CIS
A21: ARC-CO01 | B21: クラウド補完 | C21: 3. 制約と前提条件 | D21: Medium | E21: システムの配置先(リージョン/データセンター/国)の選定根拠として、データ所在地規制・ユーザー近接性(レイテンシ)・サービス提供状況・DR要件が制約条件として文書化されているか | F21: アーキテクチャ記述書の制約節に配置先選定の根拠と規制要件との対応が記載されていること | G21: データ主権・所在地規制の見落としは稼働後に発覚するとシステム移設という最大級の手戻りになる。 | H21: Well-Architected Framework for OCI > Operational Efficiency > Plan Your Deployment Strategy > Choose a Region Based on Your Customers and Data / Distributed Cloud > Follow Distributed Cloud Design Principles | I21: CORE | J21: 原則適用。案件スコープ・成果物・規制・リスク上非該当の場合はN/A根拠を記録。 | K21: SRC-OCI-WAF | L21: CONTINUITY-DR
A22: ARC-030 | B22: SWEBOK | C22: 4. アーキテクチャビューとビューポイント | D22: Critical | E22: 複数の関心事に対応するビューが存在する | F22: 少なくとも構造系ビュー(論理/モジュール)と配置系ビュー(デプロイメント)の2種類以上が作成されている | G22: 単一ビューでは多様な関心事を扱えない(multiple viewsの必要性)ため、構造と配置の最低2観点がないと運用・展開の関心事が設計から抜け落ちる。 | H22: swebok-v4a.pdf ch02 Software Architecture > 2.1 Architecture Views and Viewpoints(複数ビューによる関心事の分離) | I22: CORE | J22: 原則適用。案件スコープ・成果物・規制・リスク上非該当の場合はN/A根拠を記録。 | K22: SRC-SWEBOK-V4A
A23: ARC-031 | B23: SWEBOK | C23: 4. アーキテクチャビューとビューポイント | D23: Critical | E23: 各ビューの準拠ビューポイントが明示されている | F23: 各ビューに、対象とする関心事と使用する表記法・規約(ビューポイント定義または既知のビューポイントへの参照)が明記されている | G23: ビューポイントはビューの作成・解釈の規約を与えるものであり、これがないと図の読み方が人により異なり、誤読に基づく実装ミスを誘発する。 | H23: swebok-v4a.pdf ch02 Software Architecture > 2.1 Architecture Views and Viewpoints(ビューポイントによる規約の文書化) | I23: CORE | J23: 原則適用。案件スコープ・成果物・規制・リスク上非該当の場合はN/A根拠を記録。 | K23: SRC-SWEBOK-V4A
A24: ARC-032 | B24: SWEBOK | C24: 4. アーキテクチャビューとビューポイント | D24: High | E24: 図に凡例・記法の説明がある | F24: UML/ArchiMate等の標準記法の明記、または独自記法の場合は凡例があり、図中のすべての図形・線種の意味が判別できる | G24: 記法の定義がない図は書いた本人以外に正確に伝わらず、矢印の向きや線種の解釈違いがインタフェース設計の食い違いとして実装段階で顕在化する。 | H24: swebok-v4a.pdf ch02 Software Architecture > 2.1 Architecture Views and Viewpoints / 2.3 Architecture Description Languages and Architecture Frameworks | I24: CORE | J24: 原則適用。案件スコープ・成果物・規制・リスク上非該当の場合はN/A根拠を記録。 | K24: SRC-SWEBOK-V4A
A25: ARC-033 | B25: SWEBOK | C25: 4. アーキテクチャビューとビューポイント | D25: Critical | E25: 主要コンポーネントの責務が定義されている | F25: 構造系ビューに現れる各コンポーネントについて、責務の説明が1つ以上文章で記載されている。名前だけのコンポーネントがない | G25: アーキテクチャ設計の中核は主要コンポーネントの責務・特性・関係の特定であり、名前だけの箱は責務の重複や空白を隠し、チーム間の実装衝突を生む。 | H25: swebok-v4a.pdf ch02 Software Architecture > 3.2 Architectural Design(主要コンポーネントとその責務の特定) | I25: CORE | J25: 原則適用。案件スコープ・成果物・規制・リスク上非該当の場合はN/A根拠を記録。 | K25: SRC-SWEBOK-V4A
A26: ARC-034 | B26: SWEBOK | C26: 4. アーキテクチャビューとビューポイント | D26: High | E26: コンポーネント間のインタフェースが定義されている | F26: コンポーネント間の主要な相互作用について、インタフェース(API・プロトコル・データ形式のいずれか)が特定されている | G26: コンポーネント間の通信・相互作用が未定義だと、チームごとに勝手なプロトコル・データ形式を採用し、統合テストで初めて不整合が発覚する。 | H26: swebok-v4a.pdf ch02 Software Architecture > 3.2 Architectural Design(コンポーネントインタフェース、相互作用) | I26: CORE | J26: 原則適用。案件スコープ・成果物・規制・リスク上非該当の場合はN/A根拠を記録。 | K26: SRC-SWEBOK-V4A
A27: ARC-035 | B27: SWEBOK | C27: 4. アーキテクチャビューとビューポイント | D27: High | E27: ビュー間の整合性が確認されている | F27: 複数ビューに登場する同一要素の名前が一致している、またはビュー間対応表があり、既知の不整合が記録されている | G27: 複数ビュー導入の代償はビュー間不整合(multiple views problem)であり、対応関係の確認を怠ると「同じシステムを描いていない」図面群を根拠に実装が進む。 | H27: swebok-v4a.pdf ch02 Software Architecture > 2.1 Architecture Views and Viewpoints(multiple views problemと対応規則) | I27: CORE | J27: 原則適用。案件スコープ・成果物・規制・リスク上非該当の場合はN/A根拠を記録。 | K27: SRC-SWEBOK-V4A
A28: ARC-036 | B28: SWEBOK | C28: 4. アーキテクチャビューとビューポイント | D28: High | E28: 実行時の振る舞いが表現されている | F28: 主要ユースケースまたは品質シナリオについて、実行時の相互作用(シーケンス図、コンポーネント&コネクタビュー等)が少なくとも1つ示されている | G28: 静的構造だけでは並行性・実行時相互作用の妥当性を判断できず、性能・デッドロック等の問題が実行して初めて見つかる。 | H28: swebok-v4a.pdf ch02 Software Architecture > 2.1 Architecture Views and Viewpoints(component and connectorビューポイント、processビュー) | I28: CORE | J28: 原則適用。案件スコープ・成果物・規制・リスク上非該当の場合はN/A根拠を記録。 | K28: SRC-SWEBOK-V4A
A29: ARC-037 | B29: SWEBOK | C29: 4. アーキテクチャビューとビューポイント | D29: Medium | E29: デプロイメントビューが実行環境を具体化している | F29: ソフトウェア要素と実行環境(ノード・コンテナ・リージョン・ネットワーク境界)の対応が示され、冗長構成が関係する場合は多重度が読み取れる | G29: 配置ビューが抽象的なままだと、ネットワーク境界・冗長構成・リージョン配置の考慮漏れが本番構築時に発覚し、可用性目標が達成できない。 | H29: swebok-v4a.pdf ch02 Software Architecture > 2.1 Architecture Views and Viewpoints(deploymentビューポイント) | I29: CORE | J29: 原則適用。案件スコープ・成果物・規制・リスク上非該当の場合はN/A根拠を記録。 | K29: SRC-SWEBOK-V4A
A30: ARC-038 | B30: SWEBOK | C30: 4. アーキテクチャビューとビューポイント | D30: Medium | E30: データ/情報の観点が扱われている | F30: 主要データの所在・所有者・ライフサイクル(情報ビュー、ER概要、データフロー等)が、データが重要なシステムにおいて記述されている | G30: データの所在・所有者・ライフサイクルが不明だと、整合性責任の押し付け合いやデータ保護要件の適用漏れが起き、後からの是正コストが大きい。 | H30: swebok-v4a.pdf ch02 Software Architecture > 2.1 Architecture Views and Viewpoints(informationビューポイント) | I30: CORE | J30: 原則適用。案件スコープ・成果物・規制・リスク上非該当の場合はN/A根拠を記録。 | K30: SRC-SWEBOK-V4A
A31: ARC-039 | B31: SWEBOK | C31: 4. アーキテクチャビューとビューポイント | D31: Medium | E31: 図がソース管理可能な形式で保存されている | F31: 図の元データ(PlantUML/Mermaid/drawio等)がリポジトリで管理されている、または更新手段が明記されている | G31: 図の元データが管理されていないと更新できない「化石図」になり、ADが実態と乖離して評価・保守の情報源として機能しなくなる。 | H31: 実務補完(Docs as Code / 図のソース管理) | I31: CORE | J31: 原則適用。案件スコープ・成果物・規制・リスク上非該当の場合はN/A根拠を記録。 | K31: SRC-PRACTICE
A32: ARC-040 | B32: SWEBOK | C32: 4. アーキテクチャビューとビューポイント | D32: Low | E32: 図の粒度が適切に統一されている | F32: 1つの図の中で抽象度が混在していない(クラスレベルとシステムレベルの混在等がない)。要素数が概ね7±2〜20程度に収まるよう分割されている | G32: 1枚の図に抽象度が混在すると読者が着目すべき粒度を見失い、レビューで本質的な構造問題より枝葉の指摘に時間が費やされる。 | H32: 実務補完(C4モデル等の図解プラクティス)+ 2.1(ビューによる複雑さの管理) | I32: CORE | J32: 原則適用。案件スコープ・成果物・規制・リスク上非該当の場合はN/A根拠を記録。 | K32: SRC-PRACTICE
A33: ARC-050 | B33: SWEBOK | C33: 5. アーキテクチャスタイル・パターンと構造 | D33: High | E33: 採用したスタイル/パターンが明記されている | F33: 全体構成のアーキテクチャスタイル(レイヤード、マイクロサービス等)と主要パターンが名前付きで記載されている | G33: 採用スタイル・パターンの名前を明示することは共通語彙による共有理解の基盤であり、これがないと新規参画者が構造の意図を推測で補い誤った拡張をする。 | H33: swebok-v4a.pdf ch02 Software Architecture > 2.2 Architecture Patterns, Styles and Reference Architectures | I33: CORE | J33: 原則適用。案件スコープ・成果物・規制・リスク上非該当の場合はN/A根拠を記録。 | K33: SRC-SWEBOK-V4A
... A42: ARC-CZ01 | B42: クラウド補完 | C42: 5. アーキテクチャスタイル・パターンと構造 | D42: Medium | E42: スケールユニット(共に増減するリソースのまとまり)が設計され、成長時の拡張単位(Deployment Stamps等)としてアーキテクチャ記述に明記されている | F42: アーキテクチャ記述書にスケールユニットの構成要素・拡張増分・上限が定義されている | G42: 拡張単位が未定義だと、成長時に個別リソースの場当たり的増強となり、整合の取れないスケールで性能・信頼性が劣化する。 | H42: Azure Well-Architected Framework > パフォーマンス効率の柱 > PE:05 (Optimizing scaling and partitioning > scale unit design / Deployment Stamps pattern) | I42: CORE | J42: 原則適用。案件スコープ・成果物・規制・リスク上非該当の場合はN/A根拠を記録。 | K42: SRC-AZR-WAF
A43: ARC-060 | B43: SWEBOK | C43: 6. アーキテクチャ意思決定(ADR)と根拠 | D43: Critical | E43: 重要な意思決定がADRとして記録されている | F43: アーキテクチャに影響する主要決定(スタイル選定、主要技術選定、データ管理方針等)がそれぞれ識別子付きのADRとして存在する | G43: アーキテクチャは重要決定のネットワークとして捉えられ、決定を記録しないと後任者が理由不明の構造を壊す変更を加え、過去に棄却済みの悪手を繰り返す。 | H43: swebok-v4a.pdf ch02 Software Architecture > 2.4 Architecture as Significant Decisions | I43: CORE | J43: 原則適用。案件スコープ・成果物・規制・リスク上非該当の場合はN/A根拠を記録。 | K43: SRC-SWEBOK-V4A;SRC-CIS | L43: CONTINUITY-DR
A44: ARC-061 | B44: SWEBOK | C44: 6. アーキテクチャ意思決定(ADR)と根拠 | D44: Critical | E44: 各ADRに検討した代替案が記載されている | F44: 各ADRに採用案以外の代替案が1つ以上、利点・欠点とともに記載されている。代替案なしのADRがない | G44: 検討した代替案と棄却理由の記録は、忘れられた理由で棄却済みの案を将来再び選ぶ事故を防ぎ、条件変化時に決定を再検討する材料になる。 | H44: swebok-v4a.pdf ch02 Software Architecture > 2.4 Architecture as Significant Decisions(rationale: 検討した代替案・棄却理由の記録) | I44: CORE | J44: 原則適用。案件スコープ・成果物・規制・リスク上非該当の場合はN/A根拠を記録。 | K44: SRC-SWEBOK-V4A;SRC-CIS | L44: CONTINUITY-DR
A45: ARC-062 | B45: SWEBOK | C45: 6. アーキテクチャ意思決定(ADR)と根拠 | D45: Critical | E45: 決定の根拠(rationale)とトレードオフが記録されている | F45: 各ADRに「なぜこの案か」の理由と、犠牲にした特性(トレードオフ)が明記されている | G45: 品質属性間のトレードオフこそ設計決定の基盤であり、根拠と犠牲にした特性が残っていないと、決定の妥当性を評価も再検討もできない。 | H45: swebok-v4a.pdf ch02 Software Architecture > 2.4 Architecture as Significant Decisions(rationale、品質属性間のトレードオフ) | I45: CORE | J45: 原則適用。案件スコープ・成果物・規制・リスク上非該当の場合はN/A根拠を記録。 | K45: SRC-SWEBOK-V4A;SRC-CIS | L45: CONTINUITY-DR
A46: ARC-063 | B46: SWEBOK | C46: 6. アーキテクチャ意思決定(ADR)と根拠 | D46: High | E46: ADRにステータスと日付・決定者がある | F46: 各ADRにステータス(提案/承認/廃止/置換)、日付、決定者または合意した関係者が記載されている | G46: ステータス・日付・決定者がないと、その決定が現在有効か廃止済みかを判別できず、無効な決定に基づく実装や責任の所在不明を招く。 | H46: swebok-v4a.pdf ch02 Software Architecture > 2.4 Architecture as Significant Decisions + 実務補完(ADRテンプレート) | I46: CORE | J46: 原則適用。案件スコープ・成果物・規制・リスク上非該当の場合はN/A根拠を記録。 | K46: SRC-SWEBOK-V4A;SRC-CIS;SRC-PRACTICE | L46: CONTINUITY-DR
A47: ARC-064 | B47: SWEBOK | C47: 6. アーキテクチャ意思決定(ADR)と根拠 | D47: High | E47: ADRが対応するASR・制約に紐付いている | F47: 各ADRのコンテキスト欄に、関連するASR・関心事・制約への参照がある | G47: 決定がどの関心事・要求・制約に応えるものかが不明だと、要求変更時にどの決定を見直すべきか特定できず、影響分析が総当たりになる。 | H47: swebok-v4a.pdf ch02 Software Architecture > 2.4 Architecture as Significant Decisions(関心事・要求・資源が決定に影響) | I47: CORE | J47: 原則適用。案件スコープ・成果物・規制・リスク上非該当の場合はN/A根拠を記録。 | K47: SRC-SWEBOK-V4A;SRC-CIS | L47: CONTINUITY-DR
A48: ARC-065 | B48: SWEBOK | C48: 6. アーキテクチャ意思決定(ADR)と根拠 | D48: High | E48: 意図的な技術的負債が記録されている | F48: 期限・コスト都合で引き受けた妥協が、将来影響と返済方針(いつ・何をトリガーに解消するか)とともに記録されている。負債ゼロの場合はその旨の確認記録がある | G48: アーキテクチャ上の技術的負債は将来他者が支払うことになる経済的影響を持つため、記録しないと返済されないまま保守性・進化性を静かに侵食する。 | H48: swebok-v4a.pdf ch02 Software Architecture > 2.4 Architecture as Significant Decisions(architectural technical debt) | I48: CORE | J48: 原則適用。案件スコープ・成果物・規制・リスク上非該当の場合はN/A根拠を記録。 | K48: SRC-SWEBOK-V4A;SRC-CIS | L48: CONTINUITY-DR
A49: ARC-066 | B49: SWEBOK | C49: 6. アーキテクチャ意思決定(ADR)と根拠 | D49: Medium | E49: 廃止・置換されたADRが追跡できる | F49: 置換されたADRが削除されず「置換」ステータスで残り、後継ADRへの参照を持つ | G49: 置換された決定を消してしまうと決定のネットワーク(派生関係)の履歴が失われ、なぜ現在の構造に至ったかを追跡できなくなる。 | H49: swebok-v4a.pdf ch02 Software Architecture > 2.4 Architecture as Significant Decisions(決定のネットワーク、棄却決定の保存) | I49: CORE | J49: 原則適用。案件スコープ・成果物・規制・リスク上非該当の場合はN/A根拠を記録。 | K49: SRC-SWEBOK-V4A;SRC-CIS | L49: CONTINUITY-DR
A50: ARC-067 | B50: SWEBOK | C50: 6. アーキテクチャ意思決定(ADR)と根拠 | D50: Medium | E50: 決定の影響(正負両面)が記載されている | F50: 各ADRに、決定によって生じる正の影響と負の影響・新たな制約が記載されている | G50: 決定は後続の開発プロセスとシステムに深い影響を及ぼすため、負の影響・新たな制約を明示しないと、副作用が想定外の障害として下流工程を直撃する。 | H50: swebok-v4a.pdf ch02 Software Architecture > 2.4 Architecture as Significant Decisions(決定の帰結) | I50: CORE | J50: 原則適用。案件スコープ・成果物・規制・リスク上非該当の場合はN/A根拠を記録。 | K50: SRC-SWEBOK-V4A;SRC-CIS | L50: CONTINUITY-DR
...

Sheet 03_詳細設計
A1: ID | B1: 区分 | C1: カテゴリ | D1: 基準重要度 | E1: チェック項目 | F1: 合格基準 | G1: 意図(なぜ確認するか) | H1: 対象ドキュメント(参照箇所) | I1: 適用プロファイル | J1: 適用条件 | K1: 出典ID | L1: 重複統制グループ | M1: 案件重要度 | N1: 適用判定 | O1: 判定 | P1: 証跡・参照箇所 | Q1: 指摘・Issue ID | R1: 対応方針 | S1: 例外・リスク受容承認者 | T1: 是正期限 | U1: レビュアー | V1: レビュー日 | W1: 再確認結果
A2: DES-001 | B2: SWEBOK | C2: 1. 全般・トレーサビリティ | D2: Critical | E2: 要求から設計へのトレーサビリティが確保されている | F2: 要求ID と設計項目の対応表が存在し、対象範囲の全機能要求が少なくとも1つの設計項目に対応付いている | G2: 要求に対応しない設計(実装漏れ)や、要求のない勝手な作り込みを防ぐ。対応表がないと、テスト工程で要求の実現有無を検証できず大規模な手戻りになる。 | H2: swebok-v4a.pdf ch03 Software Design > 1.2 Context of Software Design(要求との関係)/ 1.4 Completeness(要求に対する設計の完全性) | I2: CORE | J2: 原則適用。案件スコープ・成果物・規制・リスク上非該当の場合はN/A根拠を記録。 | K2: SRC-SWEBOK-V4A
A3: DES-002 | B3: SWEBOK | C3: 1. 全般・トレーサビリティ | D3: Critical | E3: アーキテクチャ設計との整合が取れている | F3: アーキテクチャ設計書に記載されたレイヤ構造・技術選定・通信方式・横断的関心事の戦略に反する設計記述がない | G3: アーキテクチャが定めた制約(構成要素・API・スタイル・原則)に反する詳細設計は、統合時に構造の破綻や作り直しを招く。上位設計との矛盾を実装前に検出する。 | H3: swebok-v4a.pdf ch03 Software Design > 1.2 Context of Software Design(アーキテクチャとの関係)/ 2.2 Detailed Design(上位設計の制約下で進める) | I3: CORE | J3: 原則適用。案件スコープ・成果物・規制・リスク上非該当の場合はN/A根拠を記録。 | K3: SRC-SWEBOK-V4A
A4: DES-003 | B4: SWEBOK | C4: 1. 全般・トレーサビリティ | D4: High | E4: 非機能要求が設計に反映されている | F4: 性能・可用性・セキュリティ等の非機能要求それぞれについて、対応する設計方針の記載箇所を指し示せる | G4: 性能・セキュリティ等の品質懸念は全設計アプローチが扱うべき基本課題であり、後付け対応はほぼ不可能。設計時点で対応方針を持たないと本番で品質要求未達が露見する。 | H4: swebok-v4a.pdf ch03 Software Design > 1.3 Key Issues in Software Design / 3. Software Design Qualities | I4: CORE | J4: 原則適用。案件スコープ・成果物・規制・リスク上非該当の場合はN/A根拠を記録。 | K4: SRC-SWEBOK-V4A
A5: DES-004 | B5: SWEBOK | C5: 1. 全般・トレーサビリティ | D5: High | E5: 設計書の対象範囲と対象外が明記されている | F5: 「目的」「対象読者」「対象範囲」「対象外」の節が存在し、対象外項目には理由が書かれている | G5: 範囲が曖昧だと「書かれていない部分」が設計漏れなのか対象外なのか判別できず、レビューの網羅性が保証できない。読者と用途を意識した設計記述の前提となる。 | H5: swebok-v4a.pdf ch03 Software Design > 4. Recording Software Designs(読者・主題・用途に応じた設計仕様の決定) | I5: CORE | J5: 原則適用。案件スコープ・成果物・規制・リスク上非該当の場合はN/A根拠を記録。 | K5: SRC-SWEBOK-V4A
A6: DES-005 | B6: SWEBOK | C6: 1. 全般・トレーサビリティ | D6: High | E6: 用語が統一されている | F6: 同一概念に複数の名称が使われていない(用語定義または用語集があり、本文がそれに従っている) | G6: 設計は問題と解を表現する語彙を作る言語的活動であり、同一概念に複数名称があると実装者間で解釈が割れ、命名の不整合がそのままコードの不整合になる。 | H6: swebok-v4a.pdf ch03 Software Design > 1.1 Design Thinking(語彙の創出)/ 1.4 Uniformity | I6: CORE | J6: 原則適用。案件スコープ・成果物・規制・リスク上非該当の場合はN/A根拠を記録。 | K6: SRC-SWEBOK-V4A
A7: DES-006 | B7: SWEBOK | C7: 1. 全般・トレーサビリティ | D7: Medium | E7: 参照文書が特定可能である | F7: 参照する要求仕様書・アーキテクチャ設計書等が文書名+版数で列挙されている | G7: 参照文書の版が特定できないと、古い要求仕様を前提に設計・実装してしまう事故が起きる。設計変更時の影響追跡の起点にもなる。 | H7: 実務補完(IEEE 1016 SDD 実務・構成管理) | I7: CORE | J7: 原則適用。案件スコープ・成果物・規制・リスク上非該当の場合はN/A根拠を記録。 | K7: SRC-IEEE-GENERAL;SRC-PRACTICE
A8: DES-007 | B8: SWEBOK | C8: 1. 全般・トレーサビリティ | D8: Medium | E8: 実装可能な粒度まで詳細化されている | F8: 実装者の裁量として残る事項がアルゴリズムの局所的な実装詳細に限られる(モジュール責務・インタフェース・データ構造に未決定事項がない) | G8: 詳細設計は「プログラマが構築工程でコーディングできる十分な詳細さ」が完了条件。粒度不足は実装者ごとの独自判断を生み、結合時の不整合と手戻りを招く。 | H8: swebok-v4a.pdf ch03 Software Design > 2.2 Detailed Design(構築を可能にする詳細度) | I8: CORE | J8: 原則適用。案件スコープ・成果物・規制・リスク上非該当の場合はN/A根拠を記録。 | K8: SRC-SWEBOK-V4A
A9: DES-008 | B9: SWEBOK | C9: 1. 全般・トレーサビリティ | D9: Low | E9: 版管理情報がある | F9: 版数・改訂日・改訂内容の履歴が記載されている | G9: 版管理がないと、どの版をレビュー・承認したのか、実装がどの版に基づくのかが追えず、変更の見落としによる実装差異が発生する。 | H9: 実務補完(構成管理実務) | I9: CORE | J9: 原則適用。案件スコープ・成果物・規制・リスク上非該当の場合はN/A根拠を記録。 | K9: SRC-PRACTICE
A10: DES-010 | B10: SWEBOK | C10: 2. モジュール構造・設計原則 | D10: Critical | E10: モジュール一覧と責務が定義されている | F10: 対象コンポーネント内の全モジュールについて、名称と1〜2文の責務記述が存在する | G10: モジュール化は大きなソフトウェアを理解・保守可能にする基本原則。責務が未定義のモジュールは責務の重複・漏れを生み、どこに何を実装すべきか実装者が判断できない。 | H10: swebok-v4a.pdf ch03 Software Design > 1.4 Modularization / 2.2 Detailed Design(モジュールへの設計責務の割当て) | I10: CORE | J10: 原則適用。案件スコープ・成果物・規制・リスク上非該当の場合はN/A根拠を記録。 | K10: SRC-SWEBOK-V4A
A11: DES-011 | B11: SWEBOK | C11: 2. モジュール構造・設計原則 | D11: Critical | E11: モジュール間に循環依存がない | F11: 依存関係図において循環(A→B→A 等)が存在しない。存在する場合は解消策が明記されている | G11: 循環依存は疎結合の原則に反し、単体テスト不能・ビルド順序の破綻・修正影響の波及拡大を招く。設計段階でしか安価に解消できない。 | H11: swebok-v4a.pdf ch03 Software Design > 1.4 Coupling(疎結合の原則) | I11: CORE | J11: 原則適用。案件スコープ・成果物・規制・リスク上非該当の場合はN/A根拠を記録。 | K11: SRC-SWEBOK-V4A
A12: DES-012 | B12: SWEBOK | C12: 2. モジュール構造・設計原則 | D12: High | E12: 単一責任の原則に適合している | F12: 各モジュールの責務記述が単一の関心事で表現でき、「〜と〜と〜を行う」のような複数責務の羅列になっていない | G12: 複数責務を抱えるモジュールは変更理由が複数になり、無関係な修正が相互に影響して劣化が加速する。Parnas の単一責任と高凝集の原則の実地検証。 | H12: swebok-v4a.pdf ch03 Software Design > 1.4 Modularization(Parnasの単一責任)・Cohesion / 5.4 Object-Oriented Design(SOLID) | I12: CORE | J12: 原則適用。案件スコープ・成果物・規制・リスク上非該当の場合はN/A根拠を記録。 | K12: SRC-SWEBOK-V4A
A13: DES-013 | B13: SWEBOK | C13: 2. モジュール構造・設計原則 | D13: High | E13: カプセル化(情報隠蔽)が守られている | F13: 各モジュールの公開インタフェースと内部(非公開)要素が区別して記述され、内部データ構造への外部からの直接アクセスがない | G13: 内部構造が外部から直接触られると、内部変更が広範囲の呼び出し元を壊す。情報隠蔽により利用者がインタフェースの本質だけに集中でき、変更の影響が局所化される。 | H13: swebok-v4a.pdf ch03 Software Design > 1.4 Encapsulation (information hiding) | I13: CORE | J13: 原則適用。案件スコープ・成果物・規制・リスク上非該当の場合はN/A根拠を記録。 | K13: SRC-SWEBOK-V4A
... A21: DES-020 | B21: SWEBOK | C21: 3. インターフェース仕様(API仕様) | D21: Critical | E21: 全エンドポイントの入出力が型レベルで定義されている | F21: 各API について、リクエスト/レスポンスの全フィールドに型・必須/任意・制約(桁、範囲、形式)が定義されている | G21: 型・制約が未定義のAPIは、クライアント側とサーバ側で解釈が食い違い、結合テストで大量の不整合が噴出する。インタフェース定義は部品間契約の根幹。 | H21: swebok-v4a.pdf ch03 Software Design > 2.1 High-Level Design(データ形式・プロトコルの仕様化)/ 4.2 Structural Design Descriptions(IDL) | I21: CORE | J21: 原則適用。案件スコープ・成果物・規制・リスク上非該当の場合はN/A根拠を記録。 | K21: SRC-SWEBOK-V4A
A22: DES-021 | B22: SWEBOK | C22: 3. インターフェース仕様(API仕様) | D22: Critical | E22: 認証・認可方式が定義されている | F22: 認証方式(トークン形式、取得・更新方法)と、API/リソースごとの必要権限が記述されている | G22: 認証・認可が仕様化されていないAPIは、認可漏れによる不正アクセス・情報漏えいに直結する。誰が何にアクセスできるかは設計時に決めるべきセキュリティの基本。 | H22: swebok-v4a.pdf ch03 Software Design > 3.7 Assurance, Security, and Safety(不正な開示・変更・アクセスの防止) | I22: CORE | J22: 原則適用。案件スコープ・成果物・規制・リスク上非該当の場合はN/A根拠を記録。 | K22: SRC-SWEBOK-V4A | L22: SEC-IAM
A23: DES-022 | B23: SWEBOK | C23: 3. インターフェース仕様(API仕様) | D23: Critical | E23: エラーレスポンスが仕様化されている | F23: エラーコード体系、HTTPステータスとの対応、エラーレスポンスのスキーマが定義され、各APIで発生しうるエラーが列挙されている | G23: エラー仕様がないとクライアントは異常時の挙動を実装できず、障害時に原因不明のまま処理が続行される。エラーの体系化は例外処理設計の外部仕様側の要。 | H23: swebok-v4a.pdf ch03 Software Design > 3.5 Errors and Exception Handling, Fault Tolerance | I23: CORE | J23: 原則適用。案件スコープ・成果物・規制・リスク上非該当の場合はN/A根拠を記録。 | K23: SRC-SWEBOK-V4A
